Workbook

Sheet Coffres
A1: ID coffre | B1: Nom | C1: Position | D1: Description
A2: e90f29b9-f199-4889-ae16-c647b42a0b4a | B2: Coffre de l'Armurerie | C2: Salle des cartes, sous la table des cartes. | D2: Armes, Bouclier, Armures de Blancherive
A3: 52d52cb8-fa70-4f9e-8f25-d1e7aed1b342 | B3: Coffre des soldes | C3: Geoles | D3: Septimes, armes gardes spécial

Sheet Inventaire
A1: ID coffre | B1: ID objet | C1: Nom | D1: Quantité
A2: e90f29b9-f199-4889-ae16-c647b42a0b4a | B2: sentinel - city guards.esp|000806 | C2: Whiterun Guard's Helmet | D2: 5
A3: e90f29b9-f199-4889-ae16-c647b42a0b4a | B3: sentinel - city guards.esp|000800 | C3: Whiterun Guard's Armor | D3: 19
A4: e90f29b9-f199-4889-ae16-c647b42a0b4a | B4: sentinel - city guards.esp|000805 | C4: Whiterun Guard's Heavy Gauntlets | D4: 1
A5: e90f29b9-f199-4889-ae16-c647b42a0b4a | B5: sentinel - city guards.esp|000801 | C5: Whiterun Guard's Heavy Armor | D5: 19
A6: e90f29b9-f199-4889-ae16-c647b42a0b4a | B6: sentinel - city guards.esp|000808 | C6: Whiterun Guard's Heavy Helmet | D6: 29
A7: e90f29b9-f199-4889-ae16-c647b42a0b4a | B7: sentinel - city guards.esp|000809 | C7: Whiterun Light Shield | D7: 5
A8: e90f29b9-f199-4889-ae16-c647b42a0b4a | B8: sentinel - city guards.esp|00080A | C8: Whiterun Shield | D8: 1
A9: e90f29b9-f199-4889-ae16-c647b42a0b4a | B9: sentinel.esp|000906 | C9: Common Gambeson | D9: 2
A10: e90f29b9-f199-4889-ae16-c647b42a0b4a | B10: kzlhorses.esp|01024E | C10: Prisoner's Cuffs | D10: 23
A11: e90f29b9-f199-4889-ae16-c647b42a0b4a | B11: evgnnsmpaccessories.esp|00082D | C11: Quilted Mantle | D11: 2
A12: e90f29b9-f199-4889-ae16-c647b42a0b4a | B12: evgnnsmpaccessories.esp|000834 | C12: Reinforced Mantle | D12: 3
A13: e90f29b9-f199-4889-ae16-c647b42a0b4a | B13: sentinel - city guards.esp|000804 | C13: Whiterun Ceremonial Cloak | D13: 6
... A24: e90f29b9-f199-4889-ae16-c647b42a0b4a | B24: sentinel - city guards.esp|0008E0 | C24: Whiterun Sword | D24: 8
A25: 52d52cb8-fa70-4f9e-8f25-d1e7aed1b342 | C25: Epée d'argent | D25: 1

Sheet Objets
A1: ID objet | B1: Nom | C1: Type
A2: dragonborn.esm|01BFEF | B2: Zahkrii Do Dovahkiin | C2: Arme
A3: windhelmsse.esp|1252B7 | B3: Akaviri Snakesword | C3: Arme
A4: aaagranitehill.esp|3BC29A | B4: Amon's Cheese Steel Dagger | C4: Arme
A5: skyrim.esm|106252 | B5: Ancien espadon nordique ardent affûté | C5: Arme
A6: dragonborn.esm|036689 | B6: Animortis | C6: Arme
A7: skyrim.esm|06EA8B | B7: Aquilon | C7: Arme
A8: dawnguard.esm|000801 | B8: Arbalète | C8: Arme
A9: dawnguard.esm|00F19E | B9: Arbalète améliorée | C9: Arme
A10: dawnguard.esm|00D0BE | B10: Arbalète bénie | C10: Arme
A11: dawnguard.esm|00D0C7 | B11: Arbalète d'amenuisement | C11: Arme
A12: dawnguard.esm|00D0C5 | B12: Arbalète d'éclairs | C12: Arme
... A10132: skyrim.esm|03133C | B10132: Wine | C10132: Potion / nourriture

Sheet SoldesGrades
A1: Grade | B1: Solde journalière (septims)
A2: Par défaut | B2: 50
A3: Maréchal | B3: 100
A4: Commander | B4: 100
A5: Major | B5: 75
A6: Capitaine | B6: 50
A7: Lieutenant-Chef | B7: 50
A8: Lieutenant | B8: 50
A9: Sergent-Chef | B9: 50
A10: Sergent | B10: 50
A11: Caporal-Chef | B11: 50
A12: Caporal | B12: 50
A13: Garde | B13: 50
... A15: Recrue | B15: 0

Sheet HistoriqueEffectifs
A1: ID événement | B1: Date ISO | C1: ID membre | D1: Type | E1: Nom | F1: Changements JSON | G1: État JSON | H1: Source
A2: 19bb8717-fc55-43e7-aea0-a062215c33f0 | B2: 2026-09-06T11:12:57.322Z | D2: initialisation | F2: [] | G2: {} | H2: Détection
A3: aa2df3fa-8c22-4d03-9be7-b080f99c5e08 | B3: 2026-09-06T11:12:57.322Z | C3: d46f0957-73ed-4c3c-9135-84cc8f768643 | D3: reference | E3: Lazabard Jemelred | F3: [] | G3: {"prenom":"Lazabard","nom":"Jemelred","grade":"Maréchal","corps":"Etat-Major","status":"En service actif"} | H3: Détection
A4: 2ed5527f-c150-41d4-8f5c-9c03d1a2dd5f | B4: 2026-09-06T11:12:57.322Z | C4: 99c04539-4625-4073-b805-d47570970809 | D4: reference | E4: Filoki | F4: [] | G4: {"prenom":"Filoki","nom":"","grade":"Commander","corps":"Etat-Major","status":"En service actif"} | H4: Détection
A5: 19e80916-a210-4e2e-ab97-8cf999287642 | B5: 2026-09-06T11:12:57.322Z | C5: ae3bc537-6b70-4a20-bc22-394ed7a3ebed | D5: reference | E5: Dagbara Gronez | F5: [] | G5: {"prenom":"Dagbara","nom":"Gronez","grade":"Major","corps":"Etat-Major","status":"Mis en réserve"} | H5: Détection
A6: 4143667e-dc10-4a67-a015-b16afd8734e6 | B6: 2026-09-06T11:12:57.322Z | C6: 066ffa57-32e1-4df1-b986-fecbc974f94f | D6: reference | E6: Astrid Lame-Fine | F6: [] | G6: {"prenom":"Astrid","nom":"Lame-Fine","grade":"Capitaine","corps":"Cité de Blancherive","status":"En service actif"} | H6: Détection
A7: 565fada4-80a6-4ad3-bd38-94e070a1e597 | B7: 2026-09-06T11:12:57.322Z | C7: be4acc2e-1d02-4737-864e-ac54f1ff672a | D7: reference | E7: Glaemorandir Oeil-Perçant | F7: [] | G7: {"prenom":"Glaemorandir","nom":"Oeil-Perçant","grade":"Capitaine","corps":"Eclaireur","status":"En service actif"} | H7: Détection
A8: bb66b8c2-baa8-4d51-b2e6-52e00440a67b | B8: 2026-09-06T11:12:57.322Z | C8: d063b504-c415-4cfd-a859-953178822915 | D8: reference | E8: Edward Winters | F8: [] | G8: {"prenom":"Edward","nom":"Winters","grade":"Capitaine","corps":"Cité de Blancherive","status":"Mis en réserve"} | H8: Détection
A9: 905ad0a4-0911-410d-93be-6ec287e4c167 | B9: 2026-09-06T11:12:57.322Z | C9: b2cf2258-4446-43c9-b850-e157c81f93fc | D9: reference | E9: Kah-Shir Sombre Griffe | F9: [] | G9: {"prenom":"Kah-Shir","nom":"Sombre Griffe","grade":"Capitaine","corps":"Faubourgs de Blancherive","status":"En service actif"} | H9: Détection
A10: 95f772ea-a38a-4e0a-88de-8d0c4dc93b7c | B10: 2026-09-06T11:12:57.322Z | C10: f89b63e9-4f33-4f63-9666-0289c90a22e1 | D10: reference | E10: Clemnir Arc-Vif | F10: [] | G10: {"prenom":"Clemnir","nom":"Arc-Vif","grade":"Capitaine","corps":"Eclaireur","status":"Mort en service actif"} | H10: Détection
A11: a104fd1d-7aed-44c6-87d8-5bf6ba4ad457 | B11: 2026-09-06T11:12:57.322Z | C11: 3f7cf32c-5eda-447f-b5e1-9bd0d6fb6940 | D11: reference | E11: Sigurd Grisetoison | F11: [] | G11: {"prenom":"Sigurd","nom":"Grisetoison","grade":"Capitaine","corps":"Rivebois","status":"Déserteur"} | H11: Détection
A12: 6f840cc7-dbf1-47f6-9352-577524625103 | B12: 2026-09-06T11:12:57.322Z | C12: 9bd100c0-2019-43c5-807d-bcc8a177174d | D12: reference | E12: Hastelvin | F12: [] | G12: {"prenom":"Hastelvin","nom":"","grade":"Capitaine","corps":"Cap Granite","status":"En service actif"} | H12: Détection
A13: a9c65bcf-cd83-4972-9944-3a547412c790 | B13: 2026-09-06T11:12:57.322Z | C13: e194b9d1-cea0-4e22-b10f-e7dee3aec987 | D13: reference | E13: Ulfar | F13: [] | G13: {"prenom":"Ulfar","nom":"","grade":"Major","corps":"Etat-Major","status":"En service actif"} | H13: Détection
A14: b40e1512-e0d1-4e1f-9cc2-efe4087cfc7f | B14: 2026-09-06T11:12:57.322Z | C14: 3ff8c6c7-e0ec-44d3-9d43-062229456eeb | D14: reference | E14: Ronin | F14: [] | G14: {"prenom":"Ronin","nom":"","grade":"Lieutenant","corps":"Cité de Blancherive","status":"En service actif"} | H14: Détection
... A213: d7da8d20-6bc5-4ec1-8ca0-2dda7a20f5dc | B213: 2026-09-26T23:20:28.600Z | C213: 0005762a-098e-4ce4-93bc-10132427bf0f | D213: changement | E213: Crocozaure | F213: [{"type":"corps","avant":"Cité de Blancherive","apres":"Eclaireur"}] | G213: {"prenom":"Crocozaure","nom":"","grade":"Cadet","corps":"Eclaireur","status":"En service actif"} | H213: Application

Sheet Effectifs
A1: Assermenté | B1: Grade | C1: Prénom | D1: Nom | E1: Corps | F1: Spécialité | G1: Status | H1: Métier | AA1: ID membre
A2: TRUE | B2: Maréchal | C2: Lazabard | D2: Jemelred | E2: Etat-Major | F2: Garde, Collecteur de la garde | G2: En service actif | AA2: d46f0957-73ed-4c3c-9135-84cc8f768643
A3: TRUE | B3: Commander | C3: Filoki | E3: Etat-Major | F3: Garde, Collecteur de la garde | G3: En service actif | AA3: 99c04539-4625-4073-b805-d47570970809
A4: TRUE | B4: Major | C4: Dagbara | D4: Gronez | E4: Etat-Major | F4: Garde | G4: Mis en réserve | AA4: ae3bc537-6b70-4a20-bc22-394ed7a3ebed
A5: TRUE | B5: Capitaine | C5: Astrid | D5: Lame-Fine | E5: Cité de Blancherive | F5: Garde, Collecteur de la garde | G5: En service actif | H5: Chasseur | AA5: 066ffa57-32e1-4df1-b986-fecbc974f94f
A6: TRUE | B6: Capitaine | C6: Glaemorandir | D6: Oeil-Perçant | E6: Eclaireur | F6: Eclaireur, Garde, Collecteur de la garde | G6: En service actif | H6: Chasseur | AA6: be4acc2e-1d02-4737-864e-ac54f1ff672a
A7: TRUE | B7: Capitaine | C7: Edward | D7: Winters | E7: Cité de Blancherive | F7: Hird | G7: Mis en réserve | AA7: d063b504-c415-4cfd-a859-953178822915
A8: TRUE | B8: Capitaine | C8: Kah-Shir | D8: Sombre Griffe | E8: Faubourgs de Blancherive | G8: Radié du service actif | AA8: b2cf2258-4446-43c9-b850-e157c81f93fc
A9: TRUE | B9: Capitaine | C9: Clemnir | D9: Arc-Vif | E9: Eclaireur | F9: Eclaireur | G9: Mort en service actif | H9: Chasseur | AA9: f89b63e9-4f33-4f63-9666-0289c90a22e1
A10: FALSE | B10: Capitaine | C10: Sigurd | D10: Grisetoison | E10: Rivebois | F10: Garde, Collecteur de la garde | G10: Déserteur | AA10: 3f7cf32c-5eda-447f-b5e1-9bd0d6fb6940
A11: FALSE | B11: Capitaine | C11: Hastelvin | E11: Cap Granite | F11: Garde, Collecteur de la garde | G11: Démissionnaire | AA11: 9bd100c0-2019-43c5-807d-bcc8a177174d
A12: TRUE | B12: Major | C12: Ulfar | E12: Etat-Major | F12: Garde, Collecteur de la garde | G12: En service actif | AA12: e194b9d1-cea0-4e22-b10f-e7dee3aec987
A13: TRUE | B13: Lieutenant-Chef | C13: Ronin | E13: Cité de Blancherive | F13: Garde, Collecteur de la garde | G13: En service actif | H13: Guerrier | AA13: 3ff8c6c7-e0ec-44d3-9d43-062229456eeb
A14: TRUE | B14: Lieutenant | C14: Thorin | D14: Rivegel | E14: Cité de Blancherive | F14: Garde | G14: Déserteur | H14: Guerrier | AA14: bd991a26-51dd-4828-934e-6491f8612420
A15: TRUE | B15: Lieutenant-Chef | C15: Gisbern | D15: Isenbjorn | E15: Cité de Blancherive | F15: Garde | G15: Déserteur | AA15: 3337fcb2-cdd2-425e-9899-3efe84a5bf31
A16: TRUE | B16: Lieutenant | C16: Rorik | D16: Marche-Hiver | E16: Cité de Blancherive | F16: Garde, Intendant de la garde | G16: En service actif | AA16: 7f06b07a-819f-460f-b37b-0874f474bd94
A17: TRUE | B17: Sergent-Chef | C17: Erwan | E17: Cité de Blancherive | F17: Garde | G17: En service actif | AA17: 387160c7-839d-4249-b44d-61ae80f8aad4
A18: TRUE | B18: Lieutenant | C18: Daric | E18: Rivebois | F18: Garde | G18: En service actif | AA18: 90d91845-36aa-44bd-ab58-cfc0dba6f40a
A19: TRUE | B19: Caporal-Chef | C19: Ilflynn | E19: Cité de Blancherive | F19: Garde | G19: En service actif | AA19: 44162c0c-aec1-4836-bcd0-538e837f915b
A20: TRUE | B20: Sergent-Chef | C20: Magnar | D20: Traquebrume | E20: Eclaireur | F20: Eclaireur, Garde | G20: En service actif | H20: Chasseur | AA20: 8a386dc7-8b4c-4075-add4-d6bdb563f82c
A21: TRUE | B21: Lieutenant-Chef | C21: Pethiceor | D21: Le Borgne | E21: Eclaireur | F21: Eclaireur, Garde | G21: En service actif | H21: Chasseur | AA21: 089e2535-16b8-4f30-b745-f4e8247bb3dc
A22: TRUE | B22: Garde | C22: Laureen | D22: Toison-de-Sang | E22: Cité de Blancherive | F22: Eclaireur, Garde | G22: En service actif | H22: Chasseur | AA22: b4583989-fdc0-4056-a9c3-05a4acb3c5dd
A23: TRUE | B23: Garde | C23: Ma'arl | E23: Eclaireur | F23: Eclaireur, Garde | G23: En service actif | H23: Mineur | AA23: c03971ee-4407-406e-adb5-e6060c104fda
A24: TRUE | B24: Garde | C24: Andor | D24: Viraes | E24: Cité de Blancherive | F24: Garde | G24: Mis en réserve | AA24: 0edc5da4-f3d8-466c-9551-4a086cf04e6a
A25: FALSE | B25: Sergent-Chef | C25: Astrild | E25: Cité de Blancherive | F25: Garde | G25: En service actif | AA25: e46cd881-a491-4ea4-9a64-da434a735c58
A26: TRUE | B26: Caporal | C26: Athlan | E26: Rivebois | F26: Garde | G26: En service actif | AA26: b7594f74-7299-4d5c-a0df-29b71c5c2ae0
A27: FALSE | B27: Lieutenant | C27: Encore-Un-Espoir | E27: Cité de Blancherive | F27: Garde, Tortionnaire, Instructeur | G27: Démissionnaire | AA27: d7cf260e-6fc9-4f55-b7a0-872095e1d48a
A28: TRUE | B28: Garde | C28: Al'Dran | E28: Cité de Blancherive | F28: Garde | G28: Démissionnaire | AA28: b1fdb1fa-73a3-4be9-8167-fe80c5c9e26a
A29: TRUE | B29: Caporal | C29: Kendall | D29: Delamare | E29: Cité de Blancherive | F29: Garde | G29: En service actif | AA29: 2792c1dd-ac31-415d-b9fc-17fbd08549ee
A30: FALSE | B30: Garde | C30: Léonce | D30: Réve-épine | E30: Faubourgs de Blancherive | G30: Radié du service actif | AA30: f62f8cc2-8070-4dc2-8416-6edea1971841
A31: FALSE | B31: Garde | C31: Kronk | D31: Grognon | E31: Hird du Jarl | F31: Hird | G31: En service actif | AA31: 91e4da48-8791-43fe-8ff4-5b0ffe3453b4
A32: FALSE | B32: Garde | C32: Gronk | D32: Grognon | E32: Hird du Jarl | F32: Hird | G32: En service actif | AA32: 16f4937d-03da-4800-b9f3-dfec048f76f5
A33: FALSE | B33: Garde | C33: S'Khar | E33: Hird du Jarl | F33: Hird | G33: En service actif | AA33: 4cd4fcb0-0b5f-4cf0-8d04-5d7df12211f3
A34: TRUE | B34: Garde | C34: Do'Rhazir | E34: Eclaireur | F34: Eclaireur, Garde | G34: En service actif | H34: Menuisier-Charbonnier | AA34: 423e12c6-ff0e-4b0c-aa09-b1edab69bb1d
A35: FALSE | B35: Cadet | C35: Eldrim | D35: Hache-Grise | E35: Cité de Blancherive | F35: Garde | G35: Déserteur | AA35: 871d3680-6678-4e2f-b020-f57f61b8f3fa
A36: FALSE | B36: Recrue | C36: Ro'minet | E36: Cité de Blancherive | F36: Garde | G36: Radié du service actif | AA36: d2280313-4392-40e5-9b5b-0fbe1cc78ee8
A37: TRUE | B37: Garde | C37: Bjorn | D37: Kornseen | E37: Cité de Blancherive | F37: Garde | G37: En service actif | AA37: 33cfe266-c918-4bde-b0d1-d4b850aa6e55
A38: TRUE | B38: Garde | C38: Wulfgar | D38: Durrock | E38: Cité de Blancherive | F38: Garde | G38: En service actif | AA38: 762a804c-ab03-4d62-8faf-f0c4431f891a
A39: FALSE | B39: Garde | C39: Lyosha | D39: Sullapierre | E39: Cité de Blancherive | F39: Garde | G39: Mis en réserve | AA39: 3c461949-7a70-483a-a9b4-47977284876c
A40: FALSE | B40: Garde | C40: Brandon | D40: Alprazz | E40: Cité de Blancherive | F40: Garde | G40: Mis en réserve | AA40: c4151012-867f-4255-9483-8157805efc88
...

Sheet Présences
A1: Semaine | B1: Corps de garde | C1: Grade | D1: Prénom | E1: Nom | F1: Lun | G1: Mar | H1: Mer | I1: Jeu | J1: Ven | K1: Sam | L1: Dim | M1: Jours présents | N1: Solde | O1: Payé
A2: 35 | B2: Cap Granite | C2: Garde | D2: Bakhir | F2: FALSE | G2: FALSE | H2: FALSE | I2: FALSE | J2: FALSE | K2: FALSE | L2: FALSE | M2: =COUNTIF(F2:L2,TRUE) -> 0 | N2: =IF(OR(B2="Hird du Jarl",C2="Recrue"),0,IF(C2="Aspirant-Garde",M2*50/2,M2*50)) -> 0 | O2: FALSE
A3: 35 | B3: Cap Granite | C3: Garde | D3: Barnabas | E3: Tharmr | F3: FALSE | G3: FALSE | H3: FALSE | I3: FALSE | J3: FALSE | K3: FALSE | L3: FALSE | M3: =COUNTIF(F3:L3,TRUE) -> 0 | N3: =IF(OR(B3="Hird du Jarl",C3="Recrue"),0,IF(C3="Aspirant-Garde",M3*50/2,M3*50)) -> 0 | O3: FALSE | Q3: N'ajoutez jamais de ligne sur cette feuille. Si l'effectif a été modifié dans la page Effectifs, lancez le script "regenererSemaineCourante" pour ajouter les entrées manquantes ou changés tout en conservant les données précédentes.
A4: 35 | B4: Cap Granite | C4: Garde | D4: Drakgor | E4: gro-Drakar | F4: FALSE | G4: FALSE | H4: FALSE | I4: FALSE | J4: FALSE | K4: FALSE | L4: FALSE | M4: =COUNTIF(F4:L4,TRUE) -> 0 | N4: =IF(OR(B4="Hird du Jarl",C4="Recrue"),0,IF(C4="Aspirant-Garde",M4*50/2,M4*50)) -> 0 | O4: FALSE
A5: 35 | B5: Cap Granite | C5: Capitaine | D5: Hastelvin | F5: FALSE | G5: FALSE | H5: FALSE | I5: FALSE | J5: FALSE | K5: FALSE | L5: FALSE | M5: =COUNTIF(F5:L5,TRUE) -> 0 | N5: =IF(OR(B5="Hird du Jarl",C5="Recrue"),0,IF(C5="Aspirant-Garde",M5*50/2,M5*50)) -> 0 | O5: FALSE
A6: 35 | B6: Cap Granite | C6: Garde | D6: Malivor | E6: Xernes | F6: FALSE | G6: FALSE | H6: FALSE | I6: FALSE | J6: FALSE | K6: FALSE | L6: FALSE | M6: =COUNTIF(F6:L6,TRUE) -> 0 | N6: =IF(OR(B6="Hird du Jarl",C6="Recrue"),0,IF(C6="Aspirant-Garde",M6*50/2,M6*50)) -> 0 | O6: FALSE
A7: 35 | B7: Cap Granite | C7: Lieutenant-Chef | D7: Pavis | E7: Gurdalval | F7: FALSE | G7: FALSE | H7: FALSE | I7: FALSE | J7: FALSE | K7: FALSE | L7: FALSE | M7: =COUNTIF(F7:L7,TRUE) -> 0 | N7: =IF(OR(B7="Hird du Jarl",C7="Recrue"),0,IF(C7="Aspirant-Garde",M7*50/2,M7*50)) -> 0 | O7: FALSE
A8: 35 | B8: Cap Granite | C8: Garde | D8: Ragniir | E8: Coeurebene | F8: FALSE | G8: FALSE | H8: FALSE | I8: FALSE | J8: FALSE | K8: FALSE | L8: FALSE | M8: =COUNTIF(F8:L8,TRUE) -> 0 | N8: =IF(OR(B8="Hird du Jarl",C8="Recrue"),0,IF(C8="Aspirant-Garde",M8*50/2,M8*50)) -> 0 | O8: FALSE
A9: 35 | B9: Cap Granite | C9: Garde | D9: Starkos | E9: Coeurebene | F9: FALSE | G9: FALSE | H9: FALSE | I9: FALSE | J9: FALSE | K9: FALSE | L9: FALSE | M9: =COUNTIF(F9:L9,TRUE) -> 0 | N9: =IF(OR(B9="Hird du Jarl",C9="Recrue"),0,IF(C9="Aspirant-Garde",M9*50/2,M9*50)) -> 0 | O9: FALSE
A10: 35 | B10: Cité de Blancherive | C10: Garde | D10: Al'Dran | F10: TRUE | G10: TRUE | H10: TRUE | I10: TRUE | J10: TRUE | K10: TRUE | L10: TRUE | M10: =COUNTIF(F10:L10,TRUE) -> 7 | N10: =IF(OR(B10="Hird du Jarl",C10="Recrue"),0,IF(C10="Aspirant-Garde",M10*50/2,M10*50)) -> 350 | O10: TRUE
A11: 35 | B11: Cité de Blancherive | C11: Recrue | D11: Aldric | E11: Cendre-coeur | F11: FALSE | G11: FALSE | H11: FALSE | I11: FALSE | J11: FALSE | K11: TRUE | L11: FALSE | M11: =COUNTIF(F11:L11,TRUE) -> 1 | N11: =IF(OR(B11="Hird du Jarl",C11="Recrue"),0,IF(C11="Aspirant-Garde",M11*50/2,M11*50)) -> 0 | O11: FALSE
A12: 35 | B12: Cité de Blancherive | C12: Garde | D12: Andor | E12: Viraes | F12: FALSE | G12: FALSE | H12: FALSE | I12: FALSE | J12: FALSE | K12: FALSE | L12: FALSE | M12: =COUNTIF(F12:L12,TRUE) -> 0 | N12: =IF(OR(B12="Hird du Jarl",C12="Recrue"),0,IF(C12="Aspirant-Garde",M12*50/2,M12*50)) -> 0 | O12: TRUE
A13: 35 | B13: Cité de Blancherive | C13: Capitaine | D13: Astrid | E13: Lame-Fine | F13: TRUE | G13: TRUE | H13: TRUE | I13: FALSE | J13: TRUE | K13: TRUE | L13: TRUE | M13: =COUNTIF(F13:L13,TRUE) -> 6 | N13: =IF(OR(B13="Hird du Jarl",C13="Recrue"),0,IF(C13="Aspirant-Garde",M13*50/2,M13*50)) -> 300 | O13: TRUE
A14: 35 | B14: Cité de Blancherive | C14: Garde | D14: Athlan | F14: FALSE | G14: TRUE | H14: TRUE | I14: FALSE | J14: FALSE | K14: FALSE | L14: FALSE | M14: =COUNTIF(F14:L14,TRUE) -> 2 | N14: =IF(OR(B14="Hird du Jarl",C14="Recrue"),0,IF(C14="Aspirant-Garde",M14*50/2,M14*50)) -> 100 | O14: TRUE
A15: 35 | B15: Cité de Blancherive | C15: Garde | D15: Bjorn | E15: Kornseen | F15: TRUE | G15: TRUE | H15: FALSE | I15: TRUE | J15: FALSE | K15: TRUE | L15: TRUE | M15: =COUNTIF(F15:L15,TRUE) -> 5 | N15: =IF(OR(B15="Hird du Jarl",C15="Recrue"),0,IF(C15="Aspirant-Garde",M15*50/2,M15*50)) -> 250 | O15: TRUE
A16: 35 | B16: Cité de Blancherive | C16: Sergent | D16: Daric | F16: FALSE | G16: FALSE | H16: FALSE | I16: FALSE | J16: FALSE | K16: FALSE | L16: FALSE | M16: =COUNTIF(F16:L16,TRUE) -> 0 | N16: =IF(OR(B16="Hird du Jarl",C16="Recrue"),0,IF(C16="Aspirant-Garde",M16*50/2,M16*50)) -> 0 | O16: FALSE
A17: 35 | B17: Cité de Blancherive | C17: Aspirant-Garde | D17: Eldrim | E17: Hache-Grise | F17: FALSE | G17: FALSE | H17: FALSE | I17: FALSE | J17: FALSE | K17: FALSE | L17: FALSE | M17: =COUNTIF(F17:L17,TRUE) -> 0 | N17: =IF(OR(B17="Hird du Jarl",C17="Recrue"),0,IF(C17="Aspirant-Garde",M17*50/2,M17*50)) -> 0 | O17: FALSE
A18: 35 | B18: Cité de Blancherive | C18: Garde | D18: Encore-Un-Espoir | F18: FALSE | G18: FALSE | H18: FALSE | I18: FALSE | J18: FALSE | K18: FALSE | L18: FALSE | M18: =COUNTIF(F18:L18,TRUE) -> 0 | N18: =IF(OR(B18="Hird du Jarl",C18="Recrue"),0,IF(C18="Aspirant-Garde",M18*50/2,M18*50)) -> 0 | O18: FALSE
A19: 35 | B19: Cité de Blancherive | C19: Sergent | D19: Erwan | F19: TRUE | G19: TRUE | H19: FALSE | I19: TRUE | J19: FALSE | K19: TRUE | L19: TRUE | M19: =COUNTIF(F19:L19,TRUE) -> 5 | N19: =IF(OR(B19="Hird du Jarl",C19="Recrue"),0,IF(C19="Aspirant-Garde",M19*50/2,M19*50)) -> 250 | O19: TRUE
A20: 35 | B20: Cité de Blancherive | C20: Lieutenant | D20: Gisbern | E20: Isenbjorn | F20: TRUE | G20: TRUE | H20: FALSE | I20: FALSE | J20: TRUE | K20: FALSE | L20: FALSE | M20: =COUNTIF(F20:L20,TRUE) -> 3 | N20: =IF(OR(B20="Hird du Jarl",C20="Recrue"),0,IF(C20="Aspirant-Garde",M20*50/2,M20*50)) -> 150 | O20: TRUE | Q20: Solde anticipée totale de la semaine courante | R20: =SUMIF('Présences'!A2:A619,ISOWEEKNUM(TODAY()),'Présences'!N2:N619) -> 0
A21: 35 | B21: Cité de Blancherive | C21: Recrue | D21: Grub | F21: TRUE | G21: TRUE | H21: TRUE | I21: FALSE | J21: FALSE | K21: FALSE | L21: FALSE | M21: =COUNTIF(F21:L21,TRUE) -> 3 | N21: =IF(OR(B21="Hird du Jarl",C21="Recrue"),0,IF(C21="Aspirant-Garde",M21*50/2,M21*50)) -> 0 | O21: FALSE | Q21: Solde totale à payer des semaines passés | R21: =SUMIFS( 'Présences'!N2:N619, 'Présences'!N2:N619,">0", 'Présences'!O2:O619,FALSE ) -> 8500
A22: 35 | B22: Cité de Blancherive | C22: Caporal-Chef | D22: Ilflynn | F22: TRUE | G22: TRUE | H22: TRUE | I22: TRUE | J22: TRUE | K22: TRUE | L22: TRUE | M22: =COUNTIF(F22:L22,TRUE) -> 7 | N22: =IF(OR(B22="Hird du Jarl",C22="Recrue"),0,IF(C22="Aspirant-Garde",M22*50/2,M22*50)) -> 350 | O22: TRUE | Q22: Soldes impayés des semaines passés | R22: =COUNTIFS( 'Présences'!N2:N619,">0", 'Présences'!O2:O619,FALSE ) -> 47
A23: 35 | B23: Cité de Blancherive | C23: Garde | D23: Kendall | E23: Delamare | F23: TRUE | G23: TRUE | H23: FALSE | I23: TRUE | J23: FALSE | K23: TRUE | L23: TRUE | M23: =COUNTIF(F23:L23,TRUE) -> 5 | N23: =IF(OR(B23="Hird du Jarl",C23="Recrue"),0,IF(C23="Aspirant-Garde",M23*50/2,M23*50)) -> 250 | O23: TRUE
A24: 35 | B24: Cité de Blancherive | C24: Recrue | D24: Léonce | E24: Réve-épine | F24: FALSE | G24: FALSE | H24: FALSE | I24: FALSE | J24: FALSE | K24: FALSE | L24: FALSE | M24: =COUNTIF(F24:L24,TRUE) -> 0 | N24: =IF(OR(B24="Hird du Jarl",C24="Recrue"),0,IF(C24="Aspirant-Garde",M24*50/2,M24*50)) -> 0 | O24: FALSE
A25: 35 | B25: Cité de Blancherive | C25: Recrue | D25: Ro'minet | F25: TRUE | G25: FALSE | H25: FALSE | I25: FALSE | J25: FALSE | K25: FALSE | L25: FALSE | M25: =COUNTIF(F25:L25,TRUE) -> 1 | N25: =IF(OR(B25="Hird du Jarl",C25="Recrue"),0,IF(C25="Aspirant-Garde",M25*50/2,M25*50)) -> 0 | O25: FALSE
A26: 35 | B26: Cité de Blancherive | C26: Lieutenant | D26: Ronin | F26: TRUE | G26: TRUE | H26: TRUE | I26: TRUE | J26: TRUE | K26: TRUE | L26: TRUE | M26: =COUNTIF(F26:L26,TRUE) -> 7 | N26: =IF(OR(B26="Hird du Jarl",C26="Recrue"),0,IF(C26="Aspirant-Garde",M26*50/2,M26*50)) -> 350 | O26: TRUE
A27: 35 | B27: Cité de Blancherive | C27: Sergent-Chef | D27: Rorik | E27: Marche-Hiver | F27: TRUE | G27: TRUE | H27: TRUE | I27: TRUE | J27: TRUE | K27: TRUE | L27: TRUE | M27: =COUNTIF(F27:L27,TRUE) -> 7 | N27: =IF(OR(B27="Hird du Jarl",C27="Recrue"),0,IF(C27="Aspirant-Garde",M27*50/2,M27*50)) -> 350 | O27: TRUE
A28: 35 | B28: Cité de Blancherive | C28: Lieutenant-Chef | D28: Ulfar | F28: TRUE | G28: FALSE | H28: TRUE | I28: FALSE | J28: TRUE | K28: FALSE | L28: TRUE | M28: =COUNTIF(F28:L28,TRUE) -> 4 | N28: =IF(OR(B28="Hird du Jarl",C28="Recrue"),0,IF(C28="Aspirant-Garde",M28*50/2,M28*50)) -> 200 | O28: TRUE
A29: 35 | B29: Cité de Blancherive | C29: Garde | D29: Wulfgar | E29: Durrock | F29: FALSE | G29: FALSE | H29: FALSE | I29: FALSE | J29: FALSE | K29: FALSE | L29: TRUE | M29: =COUNTIF(F29:L29,TRUE) -> 1 | N29: =IF(OR(B29="Hird du Jarl",C29="Recrue"),0,IF(C29="Aspirant-Garde",M29*50/2,M29*50)) -> 50 | O29: TRUE
A30: 35 | B30: Eclaireur | C30: Recrue | D30: Do'Rhazir | F30: FALSE | G30: FALSE | H30: FALSE | I30: FALSE | J30: TRUE | K30: TRUE | L30: TRUE | M30: =COUNTIF(F30:L30,TRUE) -> 3 | N30: =IF(OR(B30="Hird du Jarl",C30="Recrue"),0,IF(C30="Aspirant-Garde",M30*50/2,M30*50)) -> 0 | O30: TRUE
A31: 35 | B31: Eclaireur | C31: Capitaine | D31: Glaemorandir | E31: Oeil-Perçant | F31: TRUE | G31: TRUE | H31: TRUE | I31: TRUE | J31: TRUE | K31: TRUE | L31: TRUE | M31: =COUNTIF(F31:L31,TRUE) -> 7 | N31: =IF(OR(B31="Hird du Jarl",C31="Recrue"),0,IF(C31="Aspirant-Garde",M31*50/2,M31*50)) -> 350 | O31: TRUE
A32: 35 | B32: Eclaireur | C32: Garde | D32: Laureen | E32: Toison-de-Sang | F32: TRUE | G32: TRUE | H32: TRUE | I32: TRUE | J32: TRUE | K32: TRUE | L32: TRUE | M32: =COUNTIF(F32:L32,TRUE) -> 7 | N32: =IF(OR(B32="Hird du Jarl",C32="Recrue"),0,IF(C32="Aspirant-Garde",M32*50/2,M32*50)) -> 350 | O32: TRUE
A33: 35 | B33: Eclaireur | C33: Recrue | D33: Ma'arl | F33: FALSE | G33: TRUE | H33: TRUE | I33: FALSE | J33: TRUE | K33: TRUE | L33: TRUE | M33: =COUNTIF(F33:L33,TRUE) -> 5 | N33: =IF(OR(B33="Hird du Jarl",C33="Recrue"),0,IF(C33="Aspirant-Garde",M33*50/2,M33*50)) -> 0 | O33: TRUE
A34: 35 | B34: Eclaireur | C34: Garde | D34: Magnar | E34: Traquebrume | F34: TRUE | G34: TRUE | H34: TRUE | I34: TRUE | J34: TRUE | K34: FALSE | L34: TRUE | M34: =COUNTIF(F34:L34,TRUE) -> 6 | N34: =IF(OR(B34="Hird du Jarl",C34="Recrue"),0,IF(C34="Aspirant-Garde",M34*50/2,M34*50)) -> 300 | O34: TRUE
A35: 35 | B35: Eclaireur | C35: Lieutenant | D35: Thorin | E35: Rivegel | F35: FALSE | G35: FALSE | H35: FALSE | I35: FALSE | J35: FALSE | K35: FALSE | L35: FALSE | M35: =COUNTIF(F35:L35,TRUE) -> 0 | N35: =IF(OR(B35="Hird du Jarl",C35="Recrue"),0,IF(C35="Aspirant-Garde",M35*50/2,M35*50)) -> 0 | O35: FALSE
A36: 35 | B36: Etat-Major | C36: Commandant | D36: Filoki | F36: TRUE | G36: TRUE | H36: TRUE | I36: TRUE | J36: TRUE | K36: TRUE | L36: TRUE | M36: =COUNTIF(F36:L36,TRUE) -> 7 | N36: =IF(OR(B36="Hird du Jarl",C36="Recrue"),0,IF(C36="Aspirant-Garde",M36*50/2,M36*50)) -> 350 | O36: TRUE
A37: 35 | B37: Etat-Major | C37: Maréchal | D37: Lazabard | E37: Jemelred | F37: FALSE | G37: TRUE | H37: FALSE | I37: FALSE | J37: TRUE | K37: FALSE | L37: FALSE | M37: =COUNTIF(F37:L37,TRUE) -> 2 | N37: =IF(OR(B37="Hird du Jarl",C37="Recrue"),0,IF(C37="Aspirant-Garde",M37*50/2,M37*50)) -> 100 | O37: TRUE
A38: 35 | B38: Faubourgs de Blancherive | C38: Sergent-Chef | D38: Astrild | F38: FALSE | G38: FALSE | H38: FALSE | I38: FALSE | J38: FALSE | K38: FALSE | L38: FALSE | M38: =COUNTIF(F38:L38,TRUE) -> 0 | N38: =IF(OR(B38="Hird du Jarl",C38="Recrue"),0,IF(C38="Aspirant-Garde",M38*50/2,M38*50)) -> 0 | O38: FALSE
A39: 35 | B39: Faubourgs de Blancherive | C39: Garde | D39: Bernis | F39: FALSE | G39: FALSE | H39: FALSE | I39: FALSE | J39: FALSE | K39: FALSE | L39: FALSE | M39: =COUNTIF(F39:L39,TRUE) -> 0 | N39: =IF(OR(B39="Hird du Jarl",C39="Recrue"),0,IF(C39="Aspirant-Garde",M39*50/2,M39*50)) -> 0 | O39: FALSE
A40: 35 | B40: Faubourgs de Blancherive | C40: Garde | D40: Darina | F40: FALSE | G40: FALSE | H40: FALSE | I40: FALSE | J40: FALSE | K40: FALSE | L40: FALSE | M40: =COUNTIF(F40:L40,TRUE) -> 0 | N40: =IF(OR(B40="Hird du Jarl",C40="Recrue"),0,IF(C40="Aspirant-Garde",M40*50/2,M40*50)) -> 0 | O40: FALSE
...

Sheet Ravitaillement
A1: Element | B1: Quantité
A2: Vegetal Soup | B2: 161
A3: Beef Stew | B3: 81
A4: Venison Stew | B4: 137

Sheet Amendes
A1: Date | B1: Garde | C1: Contrevenant | D1: Infraction | E1: Montant | F1: Payé | G1: Reversé
A2: 46267.5 | B2: Sigurd Grisetoison | C2: Jean Eude | D2: Art. 117 — Du vol dans les fermes | E2: 40 | F2: TRUE | G2: TRUE
A3: 46267.5 | B3: Erwan | C3: 'Lechatblanc'' | D3: Art. 114 — De la marche obligatoire | E3: 15 | F3: TRUE | G3: TRUE
A4: 46268.5 | B4: Wulfgar Durrock | C4: Daran la collectionneur | D4: Art. 114 — De la marche obligatoire | E4: 15 | F4: TRUE | G4: TRUE
A5: 46268.5 | B5: Ulfar | C5: Emric de la tour | D5: Art. 115 — Du visage découvert | E5: 15 | F5: TRUE | G5: TRUE
A6: 46268.5 | B6: Ulfar | C6: Moren Mont Sombre | D6: Art. 115 — Du visage découvert | E6: 15 | F6: TRUE | G6: TRUE
A7: 46269.5 | B7: Glaemorandir Oeil-Perçant | C7: Lucor | D7: Art. 115 — Du visage découvert | E7: 15 | F7: TRUE | G7: TRUE
A8: 46269.5 | B8: Glaemorandir Oeil-Perçant | C8: Georgeon Tranchon | D8: Art. 115 — Du visage découvert | E8: 15 | F8: TRUE | G8: TRUE
A9: 46269.5 | B9: Wulfgar Durrock | C9: mizma | D9: Art. 116 — Du saut des murailles | E9: 55 | F9: TRUE | G9: FALSE
A10: 46269.5 | B10: Wulfgar Durrock | C10: O reil | D10: Art. 114 — De la marche obligatoire | E10: 15 | F10: TRUE | G10: TRUE
A11: 46269.5 | B11: Wulfgar Durrock | C11: Bjorn | D11: Art. 115 — Du visage découvert | E11: 15 | F11: TRUE | G11: TRUE
A12: 46269.5 | B12: Wulfgar Durrock | C12: Bjorn | D12: Art. 115 — Du visage découvert | E12: 15 | F12: TRUE | G12: TRUE
A13: 46269.5 | B13: Wulfgar Durrock | C13: coupe les crocs | D13: Art. 114 — De la marche obligatoire | E13: 15 | F13: TRUE | G13: TRUE
... A41: 46273.5 | B41: Ilflynn | C41: Dornir rochever | D41: Art. 116 — Du saut des murailles | E41: 55 | F41: TRUE | G41: TRUE
A43: 46273.5 | B43: Erwan | C43: 'Vignar Corn'' | D43: Art. 6 — Des sanctions | F43: TRUE | G43: FALSE
A44: 46275.5 | B44: Wulfgar Durrock | C44: strenn pleure-vouivre | D44: Art. 115 — Du visage découvert | E44: 15 | F44: TRUE | G44: TRUE
A45: 46275.5 | B45: Wulfgar Durrock | C45: lucia | D45: Art. 115 — Du visage découvert | E45: 15 | F45: TRUE | G45: TRUE
A46: 46275.5 | B46: Wulfgar Durrock | C46: mizma | D46: Art. 114 — De la marche obligatoire | E46: 15 | F46: TRUE | G46: TRUE
A47: 46275.5 | B47: Erwan | C47: 'Amantus'' | D47: Art. 114 — De la marche obligatoire | E47: 15 | F47: TRUE | G47: TRUE
A48: 46276.5 | B48: Ma'arl | C48: ?? | D48: Art. 34 — De l’intrusion en propriété privée extérieure | E48: 50 | F48: TRUE | G48: TRUE
A49: 46278.5 | B49: Glaemorandir Oeil-Perçant | C49: Khajiit portant une couronne. Il prétend venir de Fortdhiver et a donné un faux nom. | D49: Motif personnalisé — Article 114 - De la marche obligatoire + 5 septimes car manque de respect et donne un faux nom | E49: 20 | F49: TRUE | G49: TRUE
A50: 46278.5 | B50: Ma'arl | C50: ?? | D50: Art. 116 — Du saut des murailles | E50: 55 | F50: TRUE | G50: TRUE
A51: 46278.5 | B51: Malivor Xernes | C51: ?? | D51: Motif personnalisé — Outrage à la garde + cours à Cap Granite | E51: 115 | F51: TRUE | G51: FALSE
A52: 46278.5 | B52: Malivor Xernes | C52: ?? | D52: Art. 114 — De la marche obligatoire | E52: 15 | F52: TRUE | G52: FALSE
A53: 46280.5 | B53: Wulfgar Durrock | C53: Sillas | D53: Art. 115 — Du visage découvert | E53: 15 | F53: TRUE | G53: FALSE
A54: 46280.5 | B54: Do'Rhazir | C54: Aranor | D54: Motif personnalisé — Art 116 : Saut de muraille La personne a été obéissante et gentil donc je lui ai seulement fait faire le blé pour payer ses crimes. Il m'a aussi donné une torche. | E54: 40 | F54: TRUE | G54: TRUE
A55: 46280.5 | B55: Do'Rhazir | C55: Astaera Griffacier | D55: Motif personnalisé — Art 116 : Saut de Muraille La personne a été compréhensive et gentil, et elle n'avait apparemment pas assez sur elle pour payer, elle m'a transmis la totalité de sa bourse. | E55: 50 | F55: TRUE | G55: TRUE
... A101: 46290.5 | B101: Filoki | C101: Kaelren veyr | D101: Motif personnalisé — Article 51 - Usurpation de fonction. L'individu s'est rendu de lui même. Il semblait vouloir dissiper le mal entendu. Peine commuée en travaux forcés. Remarque de suivit post libération: L'individu semble s'être présenter comme garde de Blancherive par le passé à plusieurs reprises, et huscarl du Thane de Cap Granite. Celui-ci semble mentir allègrement et aurait abuser de notre clémence. En cas de récidive. Un procès devant le jarl sera requis. | E101: 1 | F101: TRUE | G101: TRUE
E102: {=IF(D102="","",IFERROR(_xlfn.XLOOKUP(D102,SyncCodex!L:L,SyncCodex!M:M),""))} | F102: FALSE | G102: FALSE
E103: {=IF(D103="","",IFERROR(_xlfn.XLOOKUP(D103,SyncCodex!L:L,SyncCodex!M:M),""))} | F103: FALSE | G103: FALSE
E104: {=IF(D104="","",IFERROR(_xlfn.XLOOKUP(D104,SyncCodex!L:L,SyncCodex!M:M),""))} | F104: FALSE | G104: FALSE
E105: {=IF(D105="","",IFERROR(_xlfn.XLOOKUP(D105,SyncCodex!L:L,SyncCodex!M:M),""))} | F105: FALSE | G105: FALSE
E106: {=IF(D106="","",IFERROR(_xlfn.XLOOKUP(D106,SyncCodex!L:L,SyncCodex!M:M),""))} | F106: FALSE | G106: FALSE
E107: {=IF(D107="","",IFERROR(_xlfn.XLOOKUP(D107,SyncCodex!L:L,SyncCodex!M:M),""))} | F107: FALSE | G107: FALSE
E108: {=IF(D108="","",IFERROR(_xlfn.XLOOKUP(D108,SyncCodex!L:L,SyncCodex!M:M),""))} | F108: FALSE | G108: FALSE
E109: {=IF(D109="","",IFERROR(_xlfn.XLOOKUP(D109,SyncCodex!L:L,SyncCodex!M:M),""))} | F109: FALSE | G109: FALSE
E110: {=IF(D110="","",IFERROR(_xlfn.XLOOKUP(D110,SyncCodex!L:L,SyncCodex!M:M),""))} | F110: FALSE | G110: FALSE
E111: {=IF(D111="","",IFERROR(_xlfn.XLOOKUP(D111,SyncCodex!L:L,SyncCodex!M:M),""))} | F111: FALSE | G111: FALSE
E112: {=IF(D112="","",IFERROR(_xlfn.XLOOKUP(D112,SyncCodex!L:L,SyncCodex!M:M),""))} | F112: FALSE | G112: FALSE
E113: {=IF(D113="","",IFERROR(_xlfn.XLOOKUP(D113,SyncCodex!L:L,SyncCodex!M:M),""))} | F113: FALSE | G113: FALSE
...

Sheet Prison
A1: Date | B1: Garde | C1: Détenu | D1: Cellule | E1: Infraction | F1: Durée prévue | G1: Heure d'entrée | H1: Heure de sortie prévue | I1: Libéré | J1: Saisies sur la personne | K1: Motif / Notes
A2: 46271.5 | B2: Filoki | C2: Lokir Bjornson | D2: 2 | E2: Art. 71 — De la désertion | G2: 46271.893 | I2: TRUE | J2: Ancient Nord Sword Bouclier 'acier Casque d'acier à cornes Nord Hero Sword Northern Steel Armor Steel Cuffed Boots Steel Nordic Gauntlets Bourse de 5460 septimes | K2: La bourse serai celle de la compagnie de l'écaille Rapport réalisé en présence de Kedall Delamre et Wulfgar Durrock.
A3: 46273.5 | B3: Ilflynn | C3: Alicia | D3: 1 | E3: Art. 79 — De l’usage de faux | F3: 2 | G3: 46273.624 | H3: 46273.707 | I3: TRUE | J3: [{"id":"skyrim.esm|07A91A","nom":"Cimeterre","quantite":1},{"id":"skyrim.esm|0D8E3F","nom":"Sucrelune","quantite":7}] | K3: Pour contrebande + usage de faux (se faire passer pour une personne en mission par le penitus) 350 septims. La Cimeterre est dans le tonneau des réquisitions prisonniers, et sera rendue seulement si la personne ramène les 350 septims.
A4: 46274.5 | B4: Astrid Lame-Fine | C4: Le petit con [ 2D19B ] | D4: 1 | E4: Art. 6 — Des sanctions | G4: 46274.051 | I4: TRUE | J4: [] | K4: La saisie a été effectuer par Illflynn voir avec lui. Prie Talos. Tentative de fuite a plusieurs reprises contre des gardes armés avec les armes en mains. Refus de donner l'intégralité de ses biens. Donne des coups de poings. Non respect des tortures.
A5: 46277.5 | B5: Ilflynn | C5: Gael Loïc | E5: Motif personnalisé — Il a couru vers le trône du Jarl malgré les sommations de s’arrêter. Nouvel arrivant en Bordeciel. | F5: 1 | G5: 46277.743 | H5: 46277.785 | I5: TRUE | J5: [{"id":"skyrim.esm|02F2F4","nom":"Hache de bûcheron","quantite":1},{"id":"skyrim.esm|0E3C16","nom":"Pioche","quantite":1}] | K5: Il passera le balais dans les geôles une heure
A6: 46278.5 | B6: Ilflynn | C6: Lokir | D6: 3 | E6: Motif personnalisé — Mis aux arrêts sur ordre du Jarl, pour avoir lancé un avis de recherche sur S’karr. Affaire gérée par la Hird et la cour, un procès serait prévu ce soir. Mis en cellule par Caelir Vaelion. | F6: 24 | G6: 46278.021 | H6: 46279.021 | I6: TRUE | J6: []
A7: 46281.5 | B7: Bjorn Kornseen | C7: Altor brise dent | D7: 1 | E7: Motif personnalisé — Altor Brise-Dent ne s’est présenté à aucun des deux jugements auxquels il avait pourtant préalablement confirmé sa présence.altor s'est rendu de son plein gré à la garde pour se justifier et a collaboré sans aucun problème, en attente de jugement | F7: 1 | G7: 46281.907 | H7: 46281.949 | I7: TRUE | J7: []
A8: 46282.5 | B8: Ilflynn | C8: Elerim | D8: 4 | E8: Motif personnalisé — Mis en geôles pour suspicion d’appartenir au culte de Vermina. Identifié par Astrid Lame-Fine. | F8: 2 | G8: 46281.979 | H8: 46282.062 | I8: TRUE | J8: [] | K8: Resté une heure en geôle le temps que les vigiles soient prévenus, puis un peu moins d’une heure pour l’interroger et délibérer. Après un interrogatoire Il a été jugé que les preuves n’étaient pas assez conséquentes pour le garder en geôles ou prouver qu’il soit lié de près ou de loin au culte. Néanmoins, les vigiles pensent tout comme moi qu’il est louche et qu’il faut le surveiller. Je pense aussi qu’il a menti.
A9: 46282.5 | B9: Filoki | C9: Craknar | D9: 1 | E9: Art. 35 — De l’intrusion en propriété privée intérieure | F9: 1 | G9: 46282.448 | H9: 46282.49 | I9: TRUE | J9: [{"id":"skyrim.esm|068C79","nom":"Nord Hero Battle Axe","quantite":1},{"id":"sentinel.esp|000849","nom":"Bosmer Mask","quantite":1}]
A10: 46282.5 | B10: Ilflynn | C10: Ra'zina | D10: 1 | E10: Motif personnalisé — Art. 35 — De l’intrusion en propriété privée intérieure Art. 17 - De la rébellion Art. 16 - Des menaces aggravées | F10: 24 | G10: 46282.958 | H10: 46283.958 | I10: TRUE | J10: [{"id":"","nom":"arbalette","quantite":1,"libre":true},{"id":"","nom":"Tenu khajiit","quantite":1,"libre":true},{"id":"","nom":"potion invibilité","quantite":1,"libre":true},{"id":"","nom":"potion de soin","quantite":1,"libre":true},{"id":"","nom":"lame bosmer","quantite":2,"libre":true}]
A11: 46282.5 | B11: Magnar Traquebrume | C11: Passereau (Dar'Jazir) | D11: 3 | E11: Motif personnalisé — Art. 35 — De l’intrusion en propriété privée intérieure Art. 17 - De la rébellion Art. 16 - Des menaces aggravées | F11: 24 | G11: 46282.958 | H11: 46283.958 | I11: TRUE | J11: [{"id":"","nom":"Crochet","quantite":95,"libre":true},{"id":"","nom":"Potion invisibilité prolongé","quantite":1,"libre":true},{"id":"","nom":"Tenue Khajiit","quantite":1,"libre":true}]
A12: 46283.5 | B12: Ronin | C12: Erik Marche-Brume | D12: 2 | E12: Motif personnalisé — Article 115 : Du port du masque Article 63 : Du refus d'obtempérer | F12: 1 | G12: 46283.719 | H12: 46283.76 | I12: TRUE | J12: []
A13: 46283.5 | B13: Ilflynn | C13: Grabouille | D13: 3 | E13: Art. 57 — Du trouble à l’ordre public | F13: 1 | G13: 46283.729 | H13: 46283.771 | I13: TRUE | J13: [] | K13: 45min de balais dans les geôles pour avoir embêté le Bazar, avoir posé des questions gênante à la marchande, grimpé aux poutre et ne voulait pas sortir.
A14: 46285.5 | B14: Selene | C14: Oswald Mandus | D14: 1 | E14: Motif personnalisé — *note supplémentaire ajouté* **suivant le Codex de Blancherive** Article 14 - De l'usurpation d'identité Article 15 - Des menaces Article 16 - Des menaces aggravées Article 22 - Des violences et agressions simples Article 23 - Des violences et agressions aggravées Article 29 - De la torture, de la mutilation et de la barbarie Article 51 - De l'usurpation de fonction Article 54 - De la dissimulation du visage Article 57 - Du trouble à l'ordre public Article 63 - Du refus d'obtempérer **Suivant le Decretum de Restitutione Bonorum Imperii** Article III De l'acquisition illégale, non respecté | F14: 24 | G14: 46285.167 | H14: 46286.167 | I14: TRUE | J14: [{"id":"skyrim.esm|01BE1B","nom":"Bottes","quantite":1},{"id":"sentinel.esp|000849","nom":"Bosmer Mask","quantite":1},{"id":"skyrim.esm|013999","nom":"Épée dwemer","quantite":1},{"id":"skyrim.esm|06F393","nom":"Armure de fourrure","quantite":1},{"id":"morecraftableequipment.esp|00083C","nom":"Grey Cowl","quantite":1},{"id":"skyrim.esm|06C1DA","nom":"Vêtements","quantite":1},{"id":"skyrim.esm|0877AB","nom":"Anneau d'argent et de grenat","quantite":2},{"id":"","nom":"Baton de Foi","quantite":1,"libre":true},{"id":"","nom":"Épée Falmer","quantite":1,"libre":true},{"id":"","nom":"capuche Rogueswood","quantite":1,"libre":true},{"id":"","nom":"Leather cape","quantite":1,"libre":true}] | K14: le bâton de magie de foi ; l’épée dwemer ; ainsi que l’équipement bosmer retrouvé en sa possession sans licence
A15: 46285.5 | B15: Ilflynn | C15: Talaka | D15: 4 | E15: Motif personnalisé — Article 74 | F15: 4 | G15: 46285.74 | H15: 46285.907 | I15: TRUE | J15: [] | K15: Article 74 outrage à la cour, la garde et la chatelerie.
A16: 46285.5 | B16: Theodrek Heid | C16: Runar Corbois | D16: 2eme a gauche en rentrant par salle du trône | E16: Motif personnalisé — Suspicion complicité de l'assassinat de Zandalar | F16: 6.000001 | G16: 46285.91 | H16: 46286.16 | I16: TRUE | J16: [{"id":"sentinel.esp|000912","nom":"Large Fur Collar","quantite":1},{"id":"skyrim.esm|086985","nom":"Casque d'officier des Sombrages","quantite":1},{"id":"skyrim.esm|03EB12","nom":"Breuvage de récupération","quantite":1},{"id":"skyrim.esm|03EB11","nom":"Potion de récupération","quantite":1},{"id":"skyrim.esm|03EB02","nom":"Potion de force","quantite":1},{"id":"sentinel.esp|0008B9","nom":"Stormcloak Heavy Lamellar Boots","quantite":1},{"id":"sentinel.esp|0008C4","nom":"Stormcloak Heavy Lamellar Gauntlets","quantite":1},{"id":"sentinel.esp|000B33","nom":"Bosmer Bow","quantite":1},{"id":"skyrim.esm|01397F","nom":"Flèche d'acier","quantite":219},{"id":"skyrim.esm|013984","nom":"Hache d'armes d'acier","quantite":1},{"id":"commonclothes.esp|001874","nom":"Leather Doublet","quantite":1}] | K16: En cellule jusqu'à son jugement.
A17: 46290.5 | B17: Laureen Toison-de-Sang | C17: Orel le dévastateur | D17: 1 | E17: Motif personnalisé — Soupçon d'être un vampire, porte du masque, racket. | F17: 24 | G17: 46290.773 | H17: 46291.773 | I17: TRUE | J17: [{"id":"","nom":"Arc orc, capuche noir","quantite":1,"libre":true}] | K17: Orsimer qui manipule la magie probablement Galgarot ou l'un de ces fils. ORDRE DE GHORBASH: ne pas rentrer dans la cellule sans la présence d'un vigile. ON ATTEND LES VIGILES
A18: 46290.5 | B18: Ronin | C18: Le dévastateur | D18: 1 | E18: Motif personnalisé — -Menaces aggravées -Suspicion vampirique -Rakhet | F18: 0.1 | G18: 46290.778 | H18: 46290.782 | I18: TRUE | J18: [{"id":"","nom":"Black Cowl","quantite":1,"libre":true},{"id":"","nom":"Arc orque","quantite":1,"libre":true}] | K18: En attente de la garde de l'aube
F19: {=IF(E19="","",IFERROR(_xlfn.XLOOKUP(E19,SyncCodex!N:N,SyncCodex!O:O),""))} | H19: =IF(OR(G19="",F19=""),"",G19+(F19/24)) | I19: FALSE
F20: {=IF(E20="","",IFERROR(_xlfn.XLOOKUP(E20,SyncCodex!N:N,SyncCodex!O:O),""))} | H20: =IF(OR(G20="",F20=""),"",G20+(F20/24)) | I20: FALSE
F21: {=IF(E21="","",IFERROR(_xlfn.XLOOKUP(E21,SyncCodex!N:N,SyncCodex!O:O),""))} | H21: =IF(OR(G21="",F21=""),"",G21+(F21/24)) | I21: FALSE
F22: {=IF(E22="","",IFERROR(_xlfn.XLOOKUP(E22,SyncCodex!N:N,SyncCodex!O:O),""))} | H22: =IF(OR(G22="",F22=""),"",G22+(F22/24)) | I22: FALSE
F23: {=IF(E23="","",IFERROR(_xlfn.XLOOKUP(E23,SyncCodex!N:N,SyncCodex!O:O),""))} | H23: =IF(OR(G23="",F23=""),"",G23+(F23/24)) | I23: FALSE
F24: {=IF(E24="","",IFERROR(_xlfn.XLOOKUP(E24,SyncCodex!N:N,SyncCodex!O:O),""))} | H24: =IF(OR(G24="",F24=""),"",G24+(F24/24)) | I24: FALSE
F25: {=IF(E25="","",IFERROR(_xlfn.XLOOKUP(E25,SyncCodex!N:N,SyncCodex!O:O),""))} | H25: =IF(OR(G25="",F25=""),"",G25+(F25/24)) | I25: FALSE
F26: {=IF(E26="","",IFERROR(_xlfn.XLOOKUP(E26,SyncCodex!N:N,SyncCodex!O:O),""))} | H26: =IF(OR(G26="",F26=""),"",G26+(F26/24)) | I26: FALSE
F27: {=IF(E27="","",IFERROR(_xlfn.XLOOKUP(E27,SyncCodex!N:N,SyncCodex!O:O),""))} | H27: =IF(OR(G27="",F27=""),"",G27+(F27/24)) | I27: FALSE
F28: {=IF(E28="","",IFERROR(_xlfn.XLOOKUP(E28,SyncCodex!N:N,SyncCodex!O:O),""))} | H28: =IF(OR(G28="",F28=""),"",G28+(F28/24)) | I28: FALSE
F29: {=IF(E29="","",IFERROR(_xlfn.XLOOKUP(E29,SyncCodex!N:N,SyncCodex!O:O),""))} | H29: =IF(OR(G29="",F29=""),"",G29+(F29/24)) | I29: FALSE
F30: {=IF(E30="","",IFERROR(_xlfn.XLOOKUP(E30,SyncCodex!N:N,SyncCodex!O:O),""))} | H30: =IF(OR(G30="",F30=""),"",G30+(F30/24)) | I30: FALSE
... F997: {=IF(E997="","",IFERROR(_xlfn.XLOOKUP(E997,SyncCodex!N:N,SyncCodex!O:O),""))} | H997: =IF(OR(G997="",F997=""),"",G997+(F997/24)) | I997: FALSE

Sheet Garde de Blancherive
A1: =IFERROR(__xludf.DUMMYFUNCTION("QUERY(Effectifs!A:Z, ""SELECT * WHERE E CONTAINS 'Cité' OR E CONTAINS 'Major' ORDER BY Z ASC"", 1)"),"Assermenté") -> Assermenté | B1: =IFERROR(__xludf.DUMMYFUNCTION("""COMPUTED_VALUE"""),"Grade") -> Grade | C1: =IFERROR(__xludf.DUMMYFUNCTION("""COMPUTED_VALUE"""),"Prénom") -> Prénom | D1: =IFERROR(__xludf.DUMMYFUNCTION("""COMPUTED_VALUE"""),"Nom") -> Nom | E1: =IFERROR(__xludf.DUMMYFUNCTION("""COMPUTED_VALUE"""),"Corps") -> Corps | F1: =IFERROR(__xludf.DUMMYFUNCTION("""COMPUTED_VALUE"""),"Spécialité") -> Spécialité | G1: =IFERROR(__xludf.DUMMYFUNCTION("""COMPUTED_VALUE"""),"Status") -> Status | H1: =IFERROR(__xludf.DUMMYFUNCTION("""COMPUTED_VALUE"""),"Métier") -> Métier | I1: =IFERROR(__xludf.DUMMYFUNCTION("""COMPUTED_VALUE"""),"") | J1: =IFERROR(__xludf.DUMMYFUNCTION("""COMPUTED_VALUE"""),"") | K1: =IFERROR(__xludf.DUMMYFUNCTION("""COMPUTED_VALUE"""),"") | L1: =IFERROR(__xludf.DUMMYFUNCTION("""COMPUTED_VALUE"""),"") | M1: =IFERROR(__xludf.DUMMYFUNCTION("""COMPUTED_VALUE"""),"") | N1: =IFERROR(__xludf.DUMMYFUNCTION("""COMPUTED_VALUE"""),"") | O1: =IFERROR(__xludf.DUMMYFUNCTION("""COMPUTED_VALUE"""),"") | P1: =IFERROR(__xludf.DUMMYFUNCTION("""COMPUTED_VALUE"""),"") | ... Z1: =IFERROR(__xludf.DUMMYFUNCTION("""COMPUTED_VALUE"""),"")
A2: =IFERROR(__xludf.DUMMYFUNCTION("""COMPUTED_VALUE"""),TRUE) -> TRUE | B2: =IFERROR(__xludf.DUMMYFUNCTION("""COMPUTED_VALUE"""),"Maréchal") -> Maréchal | C2: =IFERROR(__xludf.DUMMYFUNCTION("""COMPUTED_VALUE"""),"Lazabard") -> Lazabard | D2: =IFERROR(__xludf.DUMMYFUNCTION("""COMPUTED_VALUE"""),"Jemelred") -> Jemelred | E2: =IFERROR(__xludf.DUMMYFUNCTION("""COMPUTED_VALUE"""),"Etat-Major") -> Etat-Major | F2: =IFERROR(__xludf.DUMMYFUNCTION("""COMPUTED_VALUE"""),"Garde, Collecteur de la garde") -> Garde, Collecteur de la garde | G2: =IFERROR(__xludf.DUMMYFUNCTION("""COMPUTED_VALUE"""),"En service actif") -> En service actif
A3: =IFERROR(__xludf.DUMMYFUNCTION("""COMPUTED_VALUE"""),TRUE) -> TRUE | B3: =IFERROR(__xludf.DUMMYFUNCTION("""COMPUTED_VALUE"""),"Commander") -> Commander | C3: =IFERROR(__xludf.DUMMYFUNCTION("""COMPUTED_VALUE"""),"Filoki") -> Filoki | E3: =IFERROR(__xludf.DUMMYFUNCTION("""COMPUTED_VALUE"""),"Etat-Major") -> Etat-Major | F3: =IFERROR(__xludf.DUMMYFUNCTION("""COMPUTED_VALUE"""),"Garde, Collecteur de la garde") -> Garde, Collecteur de la garde | G3: =IFERROR(__xludf.DUMMYFUNCTION("""COMPUTED_VALUE"""),"En service actif") -> En service actif
A4: =IFERROR(__xludf.DUMMYFUNCTION("""COMPUTED_VALUE"""),TRUE) -> TRUE | B4: =IFERROR(__xludf.DUMMYFUNCTION("""COMPUTED_VALUE"""),"Major") -> Major | C4: =IFERROR(__xludf.DUMMYFUNCTION("""COMPUTED_VALUE"""),"Dagbara") -> Dagbara | D4: =IFERROR(__xludf.DUMMYFUNCTION("""COMPUTED_VALUE"""),"Gronez") -> Gronez | E4: =IFERROR(__xludf.DUMMYFUNCTION("""COMPUTED_VALUE"""),"Etat-Major") -> Etat-Major | F4: =IFERROR(__xludf.DUMMYFUNCTION("""COMPUTED_VALUE"""),"Garde") -> Garde | G4: =IFERROR(__xludf.DUMMYFUNCTION("""COMPUTED_VALUE"""),"Mis en réserve") -> Mis en réserve
A5: =IFERROR(__xludf.DUMMYFUNCTION("""COMPUTED_VALUE"""),TRUE) -> TRUE | B5: =IFERROR(__xludf.DUMMYFUNCTION("""COMPUTED_VALUE"""),"Capitaine") -> Capitaine | C5: =IFERROR(__xludf.DUMMYFUNCTION("""COMPUTED_VALUE"""),"Astrid") -> Astrid | D5: =IFERROR(__xludf.DUMMYFUNCTION("""COMPUTED_VALUE"""),"Lame-Fine") -> Lame-Fine | E5: =IFERROR(__xludf.DUMMYFUNCTION("""COMPUTED_VALUE"""),"Cité de Blancherive") -> Cité de Blancherive | F5: =IFERROR(__xludf.DUMMYFUNCTION("""COMPUTED_VALUE"""),"Garde, Collecteur de la garde") -> Garde, Collecteur de la garde | G5: =IFERROR(__xludf.DUMMYFUNCTION("""COMPUTED_VALUE"""),"En service actif") -> En service actif | H5: =IFERROR(__xludf.DUMMYFUNCTION("""COMPUTED_VALUE"""),"Chasseur") -> Chasseur
A6: =IFERROR(__xludf.DUMMYFUNCTION("""COMPUTED_VALUE"""),TRUE) -> TRUE | B6: =IFERROR(__xludf.DUMMYFUNCTION("""COMPUTED_VALUE"""),"Capitaine") -> Capitaine | C6: =IFERROR(__xludf.DUMMYFUNCTION("""COMPUTED_VALUE"""),"Edward") -> Edward | D6: =IFERROR(__xludf.DUMMYFUNCTION("""COMPUTED_VALUE"""),"Winters") -> Winters | E6: =IFERROR(__xludf.DUMMYFUNCTION("""COMPUTED_VALUE"""),"Cité de Blancherive") -> Cité de Blancherive | F6: =IFERROR(__xludf.DUMMYFUNCTION("""COMPUTED_VALUE"""),"Hird") -> Hird | G6: =IFERROR(__xludf.DUMMYFUNCTION("""COMPUTED_VALUE"""),"Mis en réserve") -> Mis en réserve
A7: =IFERROR(__xludf.DUMMYFUNCTION("""COMPUTED_VALUE"""),TRUE) -> TRUE | B7: =IFERROR(__xludf.DUMMYFUNCTION("""COMPUTED_VALUE"""),"Major") -> Major | C7: =IFERROR(__xludf.DUMMYFUNCTION("""COMPUTED_VALUE"""),"Ulfar") -> Ulfar | E7: =IFERROR(__xludf.DUMMYFUNCTION("""COMPUTED_VALUE"""),"Etat-Major") -> Etat-Major | F7: =IFERROR(__xludf.DUMMYFUNCTION("""COMPUTED_VALUE"""),"Garde, Collecteur de la garde") -> Garde, Collecteur de la garde | G7: =IFERROR(__xludf.DUMMYFUNCTION("""COMPUTED_VALUE"""),"En service actif") -> En service actif
A8: =IFERROR(__xludf.DUMMYFUNCTION("""COMPUTED_VALUE"""),TRUE) -> TRUE | B8: =IFERROR(__xludf.DUMMYFUNCTION("""COMPUTED_VALUE"""),"Lieutenant-Chef") -> Lieutenant-Chef | C8: =IFERROR(__xludf.DUMMYFUNCTION("""COMPUTED_VALUE"""),"Ronin") -> Ronin | E8: =IFERROR(__xludf.DUMMYFUNCTION("""COMPUTED_VALUE"""),"Cité de Blancherive") -> Cité de Blancherive | F8: =IFERROR(__xludf.DUMMYFUNCTION("""COMPUTED_VALUE"""),"Garde, Collecteur de la garde") -> Garde, Collecteur de la garde | G8: =IFERROR(__xludf.DUMMYFUNCTION("""COMPUTED_VALUE"""),"En service actif") -> En service actif | H8: =IFERROR(__xludf.DUMMYFUNCTION("""COMPUTED_VALUE"""),"Guerrier") -> Guerrier
A9: =IFERROR(__xludf.DUMMYFUNCTION("""COMPUTED_VALUE"""),TRUE) -> TRUE | B9: =IFERROR(__xludf.DUMMYFUNCTION("""COMPUTED_VALUE"""),"Lieutenant") -> Lieutenant | C9: =IFERROR(__xludf.DUMMYFUNCTION("""COMPUTED_VALUE"""),"Thorin") -> Thorin | D9: =IFERROR(__xludf.DUMMYFUNCTION("""COMPUTED_VALUE"""),"Rivegel") -> Rivegel | E9: =IFERROR(__xludf.DUMMYFUNCTION("""COMPUTED_VALUE"""),"Cité de Blancherive") -> Cité de Blancherive | F9: =IFERROR(__xludf.DUMMYFUNCTION("""COMPUTED_VALUE"""),"Garde") -> Garde | G9: =IFERROR(__xludf.DUMMYFUNCTION("""COMPUTED_VALUE"""),"Déserteur") -> Déserteur | H9: =IFERROR(__xludf.DUMMYFUNCTION("""COMPUTED_VALUE"""),"Guerrier") -> Guerrier
A10: =IFERROR(__xludf.DUMMYFUNCTION("""COMPUTED_VALUE"""),TRUE) -> TRUE | B10: =IFERROR(__xludf.DUMMYFUNCTION("""COMPUTED_VALUE"""),"Lieutenant-Chef") -> Lieutenant-Chef | C10: =IFERROR(__xludf.DUMMYFUNCTION("""COMPUTED_VALUE"""),"Gisbern") -> Gisbern | D10: =IFERROR(__xludf.DUMMYFUNCTION("""COMPUTED_VALUE"""),"Isenbjorn") -> Isenbjorn | E10: =IFERROR(__xludf.DUMMYFUNCTION("""COMPUTED_VALUE"""),"Cité de Blancherive") -> Cité de Blancherive | F10: =IFERROR(__xludf.DUMMYFUNCTION("""COMPUTED_VALUE"""),"Garde") -> Garde | G10: =IFERROR(__xludf.DUMMYFUNCTION("""COMPUTED_VALUE"""),"Déserteur") -> Déserteur
A11: =IFERROR(__xludf.DUMMYFUNCTION("""COMPUTED_VALUE"""),TRUE) -> TRUE | B11: =IFERROR(__xludf.DUMMYFUNCTION("""COMPUTED_VALUE"""),"Lieutenant") -> Lieutenant | C11: =IFERROR(__xludf.DUMMYFUNCTION("""COMPUTED_VALUE"""),"Rorik") -> Rorik | D11: =IFERROR(__xludf.DUMMYFUNCTION("""COMPUTED_VALUE"""),"Marche-Hiver") -> Marche-Hiver | E11: =IFERROR(__xludf.DUMMYFUNCTION("""COMPUTED_VALUE"""),"Cité de Blancherive") -> Cité de Blancherive | F11: =IFERROR(__xludf.DUMMYFUNCTION("""COMPUTED_VALUE"""),"Garde, Intendant de la garde") -> Garde, Intendant de la garde | G11: =IFERROR(__xludf.DUMMYFUNCTION("""COMPUTED_VALUE"""),"En service actif") -> En service actif
A12: =IFERROR(__xludf.DUMMYFUNCTION("""COMPUTED_VALUE"""),TRUE) -> TRUE | B12: =IFERROR(__xludf.DUMMYFUNCTION("""COMPUTED_VALUE"""),"Sergent-Chef") -> Sergent-Chef | C12: =IFERROR(__xludf.DUMMYFUNCTION("""COMPUTED_VALUE"""),"Erwan") -> Erwan | E12: =IFERROR(__xludf.DUMMYFUNCTION("""COMPUTED_VALUE"""),"Cité de Blancherive") -> Cité de Blancherive | F12: =IFERROR(__xludf.DUMMYFUNCTION("""COMPUTED_VALUE"""),"Garde") -> Garde | G12: =IFERROR(__xludf.DUMMYFUNCTION("""COMPUTED_VALUE"""),"En service actif") -> En service actif
A13: =IFERROR(__xludf.DUMMYFUNCTION("""COMPUTED_VALUE"""),TRUE) -> TRUE | B13: =IFERROR(__xludf.DUMMYFUNCTION("""COMPUTED_VALUE"""),"Caporal-Chef") -> Caporal-Chef | C13: =IFERROR(__xludf.DUMMYFUNCTION("""COMPUTED_VALUE"""),"Ilflynn") -> Ilflynn | E13: =IFERROR(__xludf.DUMMYFUNCTION("""COMPUTED_VALUE"""),"Cité de Blancherive") -> Cité de Blancherive | F13: =IFERROR(__xludf.DUMMYFUNCTION("""COMPUTED_VALUE"""),"Garde") -> Garde | G13: =IFERROR(__xludf.DUMMYFUNCTION("""COMPUTED_VALUE"""),"En service actif") -> En service actif
A14: =IFERROR(__xludf.DUMMYFUNCTION("""COMPUTED_VALUE"""),TRUE) -> TRUE | B14: =IFERROR(__xludf.DUMMYFUNCTION("""COMPUTED_VALUE"""),"Garde") -> Garde | C14: =IFERROR(__xludf.DUMMYFUNCTION("""COMPUTED_VALUE"""),"Laureen") -> Laureen | D14: =IFERROR(__xludf.DUMMYFUNCTION("""COMPUTED_VALUE"""),"Toison-de-Sang") -> Toison-de-Sang | E14: =IFERROR(__xludf.DUMMYFUNCTION("""COMPUTED_VALUE"""),"Cité de Blancherive") -> Cité de Blancherive | F14: =IFERROR(__xludf.DUMMYFUNCTION("""COMPUTED_VALUE"""),"Eclaireur, Garde") -> Eclaireur, Garde | G14: =IFERROR(__xludf.DUMMYFUNCTION("""COMPUTED_VALUE"""),"En service actif") -> En service actif | H14: =IFERROR(__xludf.DUMMYFUNCTION("""COMPUTED_VALUE"""),"Chasseur") -> Chasseur
A15: =IFERROR(__xludf.DUMMYFUNCTION("""COMPUTED_VALUE"""),TRUE) -> TRUE | B15: =IFERROR(__xludf.DUMMYFUNCTION("""COMPUTED_VALUE"""),"Garde") -> Garde | C15: =IFERROR(__xludf.DUMMYFUNCTION("""COMPUTED_VALUE"""),"Andor") -> Andor | D15: =IFERROR(__xludf.DUMMYFUNCTION("""COMPUTED_VALUE"""),"Viraes") -> Viraes | E15: =IFERROR(__xludf.DUMMYFUNCTION("""COMPUTED_VALUE"""),"Cité de Blancherive") -> Cité de Blancherive | F15: =IFERROR(__xludf.DUMMYFUNCTION("""COMPUTED_VALUE"""),"Garde") -> Garde | G15: =IFERROR(__xludf.DUMMYFUNCTION("""COMPUTED_VALUE"""),"Mis en réserve") -> Mis en réserve
A16: =IFERROR(__xludf.DUMMYFUNCTION("""COMPUTED_VALUE"""),FALSE) -> FALSE | B16: =IFERROR(__xludf.DUMMYFUNCTION("""COMPUTED_VALUE"""),"Sergent-Chef") -> Sergent-Chef | C16: =IFERROR(__xludf.DUMMYFUNCTION("""COMPUTED_VALUE"""),"Astrild") -> Astrild | E16: =IFERROR(__xludf.DUMMYFUNCTION("""COMPUTED_VALUE"""),"Cité de Blancherive") -> Cité de Blancherive | F16: =IFERROR(__xludf.DUMMYFUNCTION("""COMPUTED_VALUE"""),"Garde") -> Garde | G16: =IFERROR(__xludf.DUMMYFUNCTION("""COMPUTED_VALUE"""),"En service actif") -> En service actif
A17: =IFERROR(__xludf.DUMMYFUNCTION("""COMPUTED_VALUE"""),FALSE) -> FALSE | B17: =IFERROR(__xludf.DUMMYFUNCTION("""COMPUTED_VALUE"""),"Lieutenant") -> Lieutenant | C17: =IFERROR(__xludf.DUMMYFUNCTION("""COMPUTED_VALUE"""),"Encore-Un-Espoir") -> Encore-Un-Espoir | E17: =IFERROR(__xludf.DUMMYFUNCTION("""COMPUTED_VALUE"""),"Cité de Blancherive") -> Cité de Blancherive | F17: =IFERROR(__xludf.DUMMYFUNCTION("""COMPUTED_VALUE"""),"Garde, Tortionnaire, Instructeur") -> Garde, Tortionnaire, Instructeur | G17: =IFERROR(__xludf.DUMMYFUNCTION("""COMPUTED_VALUE"""),"Démissionnaire") -> Démissionnaire
A18: =IFERROR(__xludf.DUMMYFUNCTION("""COMPUTED_VALUE"""),TRUE) -> TRUE | B18: =IFERROR(__xludf.DUMMYFUNCTION("""COMPUTED_VALUE"""),"Garde") -> Garde | C18: =IFERROR(__xludf.DUMMYFUNCTION("""COMPUTED_VALUE"""),"Al'Dran") -> Al'Dran | E18: =IFERROR(__xludf.DUMMYFUNCTION("""COMPUTED_VALUE"""),"Cité de Blancherive") -> Cité de Blancherive | F18: =IFERROR(__xludf.DUMMYFUNCTION("""COMPUTED_VALUE"""),"Garde") -> Garde | G18: =IFERROR(__xludf.DUMMYFUNCTION("""COMPUTED_VALUE"""),"Démissionnaire") -> Démissionnaire
A19: =IFERROR(__xludf.DUMMYFUNCTION("""COMPUTED_VALUE"""),TRUE) -> TRUE | B19: =IFERROR(__xludf.DUMMYFUNCTION("""COMPUTED_VALUE"""),"Caporal") -> Caporal | C19: =IFERROR(__xludf.DUMMYFUNCTION("""COMPUTED_VALUE"""),"Kendall") -> Kendall | D19: =IFERROR(__xludf.DUMMYFUNCTION("""COMPUTED_VALUE"""),"Delamare") -> Delamare | E19: =IFERROR(__xludf.DUMMYFUNCTION("""COMPUTED_VALUE"""),"Cité de Blancherive") -> Cité de Blancherive | F19: =IFERROR(__xludf.DUMMYFUNCTION("""COMPUTED_VALUE"""),"Garde") -> Garde | G19: =IFERROR(__xludf.DUMMYFUNCTION("""COMPUTED_VALUE"""),"En service actif") -> En service actif
A20: =IFERROR(__xludf.DUMMYFUNCTION("""COMPUTED_VALUE"""),FALSE) -> FALSE | B20: =IFERROR(__xludf.DUMMYFUNCTION("""COMPUTED_VALUE"""),"Cadet") -> Cadet | C20: =IFERROR(__xludf.DUMMYFUNCTION("""COMPUTED_VALUE"""),"Eldrim") -> Eldrim | D20: =IFERROR(__xludf.DUMMYFUNCTION("""COMPUTED_VALUE"""),"Hache-Grise") -> Hache-Grise | E20: =IFERROR(__xludf.DUMMYFUNCTION("""COMPUTED_VALUE"""),"Cité de Blancherive") -> Cité de Blancherive | F20: =IFERROR(__xludf.DUMMYFUNCTION("""COMPUTED_VALUE"""),"Garde") -> Garde | G20: =IFERROR(__xludf.DUMMYFUNCTION("""COMPUTED_VALUE"""),"Déserteur") -> Déserteur
A21: =IFERROR(__xludf.DUMMYFUNCTION("""COMPUTED_VALUE"""),FALSE) -> FALSE | B21: =IFERROR(__xludf.DUMMYFUNCTION("""COMPUTED_VALUE"""),"Recrue") -> Recrue | C21: =IFERROR(__xludf.DUMMYFUNCTION("""COMPUTED_VALUE"""),"Ro'minet") -> Ro'minet | E21: =IFERROR(__xludf.DUMMYFUNCTION("""COMPUTED_VALUE"""),"Cité de Blancherive") -> Cité de Blancherive | F21: =IFERROR(__xludf.DUMMYFUNCTION("""COMPUTED_VALUE"""),"Garde") -> Garde | G21: =IFERROR(__xludf.DUMMYFUNCTION("""COMPUTED_VALUE"""),"Radié du service actif") -> Radié du service actif
A22: =IFERROR(__xludf.DUMMYFUNCTION("""COMPUTED_VALUE"""),TRUE) -> TRUE | B22: =IFERROR(__xludf.DUMMYFUNCTION("""COMPUTED_VALUE"""),"Garde") -> Garde | C22: =IFERROR(__xludf.DUMMYFUNCTION("""COMPUTED_VALUE"""),"Bjorn") -> Bjorn | D22: =IFERROR(__xludf.DUMMYFUNCTION("""COMPUTED_VALUE"""),"Kornseen") -> Kornseen | E22: =IFERROR(__xludf.DUMMYFUNCTION("""COMPUTED_VALUE"""),"Cité de Blancherive") -> Cité de Blancherive | F22: =IFERROR(__xludf.DUMMYFUNCTION("""COMPUTED_VALUE"""),"Garde") -> Garde | G22: =IFERROR(__xludf.DUMMYFUNCTION("""COMPUTED_VALUE"""),"En service actif") -> En service actif
A23: =IFERROR(__xludf.DUMMYFUNCTION("""COMPUTED_VALUE"""),TRUE) -> TRUE | B23: =IFERROR(__xludf.DUMMYFUNCTION("""COMPUTED_VALUE"""),"Garde") -> Garde | C23: =IFERROR(__xludf.DUMMYFUNCTION("""COMPUTED_VALUE"""),"Wulfgar") -> Wulfgar | D23: =IFERROR(__xludf.DUMMYFUNCTION("""COMPUTED_VALUE"""),"Durrock") -> Durrock | E23: =IFERROR(__xludf.DUMMYFUNCTION("""COMPUTED_VALUE"""),"Cité de Blancherive") -> Cité de Blancherive | F23: =IFERROR(__xludf.DUMMYFUNCTION("""COMPUTED_VALUE"""),"Garde") -> Garde | G23: =IFERROR(__xludf.DUMMYFUNCTION("""COMPUTED_VALUE"""),"En service actif") -> En service actif
A24: =IFERROR(__xludf.DUMMYFUNCTION("""COMPUTED_VALUE"""),FALSE) -> FALSE | B24: =IFERROR(__xludf.DUMMYFUNCTION("""COMPUTED_VALUE"""),"Garde") -> Garde | C24: =IFERROR(__xludf.DUMMYFUNCTION("""COMPUTED_VALUE"""),"Lyosha ") -> Lyosha | D24: =IFERROR(__xludf.DUMMYFUNCTION("""COMPUTED_VALUE"""),"Sullapierre") -> Sullapierre | E24: =IFERROR(__xludf.DUMMYFUNCTION("""COMPUTED_VALUE"""),"Cité de Blancherive") -> Cité de Blancherive | F24: =IFERROR(__xludf.DUMMYFUNCTION("""COMPUTED_VALUE"""),"Garde") -> Garde | G24: =IFERROR(__xludf.DUMMYFUNCTION("""COMPUTED_VALUE"""),"Mis en réserve") -> Mis en réserve
A25: =IFERROR(__xludf.DUMMYFUNCTION("""COMPUTED_VALUE"""),FALSE) -> FALSE | B25: =IFERROR(__xludf.DUMMYFUNCTION("""COMPUTED_VALUE"""),"Garde") -> Garde | C25: =IFERROR(__xludf.DUMMYFUNCTION("""COMPUTED_VALUE"""),"Brandon ") -> Brandon | D25: =IFERROR(__xludf.DUMMYFUNCTION("""COMPUTED_VALUE"""),"Alprazz") -> Alprazz | E25: =IFERROR(__xludf.DUMMYFUNCTION("""COMPUTED_VALUE"""),"Cité de Blancherive") -> Cité de Blancherive | F25: =IFERROR(__xludf.DUMMYFUNCTION("""COMPUTED_VALUE"""),"Garde") -> Garde | G25: =IFERROR(__xludf.DUMMYFUNCTION("""COMPUTED_VALUE"""),"Mis en réserve") -> Mis en réserve
A26: =IFERROR(__xludf.DUMMYFUNCTION("""COMPUTED_VALUE"""),TRUE) -> TRUE | B26: =IFERROR(__xludf.DUMMYFUNCTION("""COMPUTED_VALUE"""),"Garde") -> Garde | C26: =IFERROR(__xludf.DUMMYFUNCTION("""COMPUTED_VALUE"""),"Aldric") -> Aldric | D26: =IFERROR(__xludf.DUMMYFUNCTION("""COMPUTED_VALUE"""),"Cendre-coeur") -> Cendre-coeur | E26: =IFERROR(__xludf.DUMMYFUNCTION("""COMPUTED_VALUE"""),"Cité de Blancherive") -> Cité de Blancherive | F26: =IFERROR(__xludf.DUMMYFUNCTION("""COMPUTED_VALUE"""),"Garde") -> Garde | G26: =IFERROR(__xludf.DUMMYFUNCTION("""COMPUTED_VALUE"""),"En service actif") -> En service actif
A27: =IFERROR(__xludf.DUMMYFUNCTION("""COMPUTED_VALUE"""),FALSE) -> FALSE | B27: =IFERROR(__xludf.DUMMYFUNCTION("""COMPUTED_VALUE"""),"Recrue") -> Recrue | C27: =IFERROR(__xludf.DUMMYFUNCTION("""COMPUTED_VALUE"""),"Aldrok") -> Aldrok | E27: =IFERROR(__xludf.DUMMYFUNCTION("""COMPUTED_VALUE"""),"Cité de Blancherive") -> Cité de Blancherive | F27: =IFERROR(__xludf.DUMMYFUNCTION("""COMPUTED_VALUE"""),"Garde") -> Garde | G27: =IFERROR(__xludf.DUMMYFUNCTION("""COMPUTED_VALUE"""),"Radié du service actif") -> Radié du service actif
