Workbook

Sheet Vue globale
H2: Effectif total de la garde en service | I2: =COUNTIFS(Effectifs!B2:B1000,"<>",Effectifs!G2:G1000,"En service actif") -> 64 | K2: Solde hebdomadaire individuelle | L2: 50 | N2: Garde ayant une absence supérieure à 5 jours
K3: Budget hebdomadaire maximal | L3: =L2*7*I2 -> 22400 | N3: Garde | O3: Dernière présence
H5: =IFERROR(__xludf.DUMMYFUNCTION("QUERY( Effectifs!E2:G1000, ""SELECT E, COUNT(E) WHERE E IS NOT NULL AND G = 'En service actif' GROUP BY E ORDER BY COUNT(E) DESC LABEL E 'Corps de garde', COUNT(E) 'Effectif actif'"", 0 )"),"Corps de garde") -> Corps de garde | I5: =IFERROR(__xludf.DUMMYFUNCTION("""COMPUTED_VALUE"""),"Effectif actif") -> Effectif actif | K5: =IFERROR(__xludf.DUMMYFUNCTION("QUERY( Effectifs!E2:G1000, ""SELECT E, COUNT(E) * ""&(L2*7)&"" WHERE E IS NOT NULL AND G = 'En service actif' GROUP BY E ORDER BY COUNT(E) * ""&(L2*7)&"" DESC LABEL E 'Corps de garde', COUNT(E) * ""&(L2*7)&"" 'Budget maximal hebd"&"omadaire'"", 0 )"),"Corps de garde") -> Corps de garde | L5: =IFERROR(__xludf.DUMMYFUNCTION("""COMPUTED_VALUE"""),"Budget maximal hebdomadaire") -> Budget maximal hebdomadaire | N5: =IFERROR(__xludf.DUMMYFUNCTION("LET( semaines,FILTER('Présences'!A2:A1000,'Présences'!A2:A1000<>""""), pPrenoms,FILTER('Présences'!D2:D1000,'Présences'!A2:A1000<>""""), pNoms,FILTER('Présences'!E2:E1000,'Présences'!A2:A1000<>""""), jours,FILTER('Présences'!F2:L1000,'Présences'!A"&"2:A1000<>""""), lundiS1, DATE(YEAR(TODAY()),1,4) -WEEKDAY(DATE(YEAR(TODAY()),1,4),2) +1, dates, MAKEARRAY( ROWS(semaines), 7, LAMBDA(r,c, lundiS1 +(INDEX(semaines,r)-1)*7 +(c-1) ) )"&", personnesPresence, MAKEARRAY( ROWS(pPrenoms), 7, LAMBDA(r,c, TRIM( INDEX(pPrenoms,r) &"" ""& INDEX(pNoms,r) ) ) ), gardes, UNIQUE( FILTER( TRIM(Effecti"&"fs!C2:C1000&"" ""&Effectifs!D2:D1000), Effectifs!G2:G1000=""En service actif"", ((Effectifs!C2:C1000<>"""")+(Effectifs!D2:D1000<>""""))>0 ) ), dernieres, MAP( gardes, LAMBDA(garde, IFERROR( MA"&"X( FILTER( TOCOL(dates), TOCOL(personnesPresence)=garde, TOCOL(jours)=TRUE ) ), """" ) ) ), absents, FILTER( HSTACK(gardes,dernieres), "&" dernieres<>"""", dernieres<TODAY()-5 ), jamaisPresents, FILTER( gardes, dernieres="""" ), VSTACK( HSTACK(""— Absents depuis plusieurs jours —"",""""), absents, HSTACK(""— Jamais reporté présents —"","""")"&", HSTACK( jamaisPresents, MAP(jamaisPresents,LAMBDA(garde,""Jamais présent"")) ) ) )"),"— Absents depuis plusieurs jours —") -> — Absents depuis plusieurs jours — | O5: =IFERROR(__xludf.DUMMYFUNCTION("""COMPUTED_VALUE"""),"")
H6: =IFERROR(__xludf.DUMMYFUNCTION("""COMPUTED_VALUE"""),"Cité de Blancherive") -> Cité de Blancherive | I6: =IFERROR(__xludf.DUMMYFUNCTION("""COMPUTED_VALUE"""),17.0) -> 17 | K6: =IFERROR(__xludf.DUMMYFUNCTION("""COMPUTED_VALUE"""),"Cité de Blancherive") -> Cité de Blancherive | L6: =IFERROR(__xludf.DUMMYFUNCTION("""COMPUTED_VALUE"""),5950.0) -> 5950 | N6: =IFERROR(__xludf.DUMMYFUNCTION("""COMPUTED_VALUE"""),"Andor Viraes") -> Andor Viraes | O6: =IFERROR(__xludf.DUMMYFUNCTION("""COMPUTED_VALUE"""),46259.0) -> 46259
H7: =IFERROR(__xludf.DUMMYFUNCTION("""COMPUTED_VALUE"""),"Faubourgs de Blancherive") -> Faubourgs de Blancherive | I7: =IFERROR(__xludf.DUMMYFUNCTION("""COMPUTED_VALUE"""),12.0) -> 12 | K7: =IFERROR(__xludf.DUMMYFUNCTION("""COMPUTED_VALUE"""),"Faubourgs de Blancherive") -> Faubourgs de Blancherive | L7: =IFERROR(__xludf.DUMMYFUNCTION("""COMPUTED_VALUE"""),4200.0) -> 4200 | N7: =IFERROR(__xludf.DUMMYFUNCTION("""COMPUTED_VALUE"""),"— Jamais reporté présents —") -> — Jamais reporté présents — | O7: =IFERROR(__xludf.DUMMYFUNCTION("""COMPUTED_VALUE"""),"")
H8: =IFERROR(__xludf.DUMMYFUNCTION("""COMPUTED_VALUE"""),"Hird du Jarl") -> Hird du Jarl | I8: =IFERROR(__xludf.DUMMYFUNCTION("""COMPUTED_VALUE"""),11.0) -> 11 | K8: =IFERROR(__xludf.DUMMYFUNCTION("""COMPUTED_VALUE"""),"Hird du Jarl") -> Hird du Jarl | L8: =IFERROR(__xludf.DUMMYFUNCTION("""COMPUTED_VALUE"""),3850.0) -> 3850 | N8: =IFERROR(__xludf.DUMMYFUNCTION("""COMPUTED_VALUE"""),"Hastelvin") -> Hastelvin | O8: =IFERROR(__xludf.DUMMYFUNCTION("""COMPUTED_VALUE"""),"Jamais présent") -> Jamais présent
H9: =IFERROR(__xludf.DUMMYFUNCTION("""COMPUTED_VALUE"""),"Cap Granite") -> Cap Granite | I9: =IFERROR(__xludf.DUMMYFUNCTION("""COMPUTED_VALUE"""),8.0) -> 8 | K9: =IFERROR(__xludf.DUMMYFUNCTION("""COMPUTED_VALUE"""),"Cap Granite") -> Cap Granite | L9: =IFERROR(__xludf.DUMMYFUNCTION("""COMPUTED_VALUE"""),2800.0) -> 2800 | N9: =IFERROR(__xludf.DUMMYFUNCTION("""COMPUTED_VALUE"""),"Thorin Rivegel") -> Thorin Rivegel | O9: =IFERROR(__xludf.DUMMYFUNCTION("""COMPUTED_VALUE"""),"Jamais présent") -> Jamais présent
H10: =IFERROR(__xludf.DUMMYFUNCTION("""COMPUTED_VALUE"""),"Eclaireur") -> Eclaireur | I10: =IFERROR(__xludf.DUMMYFUNCTION("""COMPUTED_VALUE"""),6.0) -> 6 | K10: =IFERROR(__xludf.DUMMYFUNCTION("""COMPUTED_VALUE"""),"Eclaireur") -> Eclaireur | L10: =IFERROR(__xludf.DUMMYFUNCTION("""COMPUTED_VALUE"""),2100.0) -> 2100 | N10: =IFERROR(__xludf.DUMMYFUNCTION("""COMPUTED_VALUE"""),"Kronk Grognon") -> Kronk Grognon | O10: =IFERROR(__xludf.DUMMYFUNCTION("""COMPUTED_VALUE"""),"Jamais présent") -> Jamais présent
H11: =IFERROR(__xludf.DUMMYFUNCTION("""COMPUTED_VALUE"""),"Rivebois") -> Rivebois | I11: =IFERROR(__xludf.DUMMYFUNCTION("""COMPUTED_VALUE"""),6.0) -> 6 | K11: =IFERROR(__xludf.DUMMYFUNCTION("""COMPUTED_VALUE"""),"Rivebois") -> Rivebois | L11: =IFERROR(__xludf.DUMMYFUNCTION("""COMPUTED_VALUE"""),2100.0) -> 2100 | N11: =IFERROR(__xludf.DUMMYFUNCTION("""COMPUTED_VALUE"""),"Gronk Grognon") -> Gronk Grognon | O11: =IFERROR(__xludf.DUMMYFUNCTION("""COMPUTED_VALUE"""),"Jamais présent") -> Jamais présent
H12: =IFERROR(__xludf.DUMMYFUNCTION("""COMPUTED_VALUE"""),"Bois-de-Chêne") -> Bois-de-Chêne | I12: =IFERROR(__xludf.DUMMYFUNCTION("""COMPUTED_VALUE"""),2.0) -> 2 | K12: =IFERROR(__xludf.DUMMYFUNCTION("""COMPUTED_VALUE"""),"Bois-de-Chêne") -> Bois-de-Chêne | L12: =IFERROR(__xludf.DUMMYFUNCTION("""COMPUTED_VALUE"""),700.0) -> 700 | N12: =IFERROR(__xludf.DUMMYFUNCTION("""COMPUTED_VALUE"""),"S'Khar") -> S'Khar | O12: =IFERROR(__xludf.DUMMYFUNCTION("""COMPUTED_VALUE"""),"Jamais présent") -> Jamais présent
H13: =IFERROR(__xludf.DUMMYFUNCTION("""COMPUTED_VALUE"""),"Etat-Major") -> Etat-Major | I13: =IFERROR(__xludf.DUMMYFUNCTION("""COMPUTED_VALUE"""),2.0) -> 2 | K13: =IFERROR(__xludf.DUMMYFUNCTION("""COMPUTED_VALUE"""),"Etat-Major") -> Etat-Major | L13: =IFERROR(__xludf.DUMMYFUNCTION("""COMPUTED_VALUE"""),700.0) -> 700 | N13: =IFERROR(__xludf.DUMMYFUNCTION("""COMPUTED_VALUE"""),"Eldrim Hache-Grise") -> Eldrim Hache-Grise | O13: =IFERROR(__xludf.DUMMYFUNCTION("""COMPUTED_VALUE"""),"Jamais présent") -> Jamais présent
N14: =IFERROR(__xludf.DUMMYFUNCTION("""COMPUTED_VALUE"""),"Njalda") -> Njalda | O14: =IFERROR(__xludf.DUMMYFUNCTION("""COMPUTED_VALUE"""),"Jamais présent") -> Jamais présent
N15: =IFERROR(__xludf.DUMMYFUNCTION("""COMPUTED_VALUE"""),"Darina") -> Darina | O15: =IFERROR(__xludf.DUMMYFUNCTION("""COMPUTED_VALUE"""),"Jamais présent") -> Jamais présent
N16: =IFERROR(__xludf.DUMMYFUNCTION("""COMPUTED_VALUE"""),"Bernis") -> Bernis | O16: =IFERROR(__xludf.DUMMYFUNCTION("""COMPUTED_VALUE"""),"Jamais présent") -> Jamais présent
N17: =IFERROR(__xludf.DUMMYFUNCTION("""COMPUTED_VALUE"""),"Drakgor gro-Drakar") -> Drakgor gro-Drakar | O17: =IFERROR(__xludf.DUMMYFUNCTION("""COMPUTED_VALUE"""),"Jamais présent") -> Jamais présent
N18: =IFERROR(__xludf.DUMMYFUNCTION("""COMPUTED_VALUE"""),"Gorbash Tête-de-Pierre") -> Gorbash Tête-de-Pierre | O18: =IFERROR(__xludf.DUMMYFUNCTION("""COMPUTED_VALUE"""),"Jamais présent") -> Jamais présent
N19: =IFERROR(__xludf.DUMMYFUNCTION("""COMPUTED_VALUE"""),"Armand De Valclair") -> Armand De Valclair | O19: =IFERROR(__xludf.DUMMYFUNCTION("""COMPUTED_VALUE"""),"Jamais présent") -> Jamais présent
N20: =IFERROR(__xludf.DUMMYFUNCTION("""COMPUTED_VALUE"""),"Si'Yara dite Fou") -> Si'Yara dite Fou | O20: =IFERROR(__xludf.DUMMYFUNCTION("""COMPUTED_VALUE"""),"Jamais présent") -> Jamais présent
N21: =IFERROR(__xludf.DUMMYFUNCTION("""COMPUTED_VALUE"""),"Lokh Tar") -> Lokh Tar | O21: =IFERROR(__xludf.DUMMYFUNCTION("""COMPUTED_VALUE"""),"Jamais présent") -> Jamais présent
N22: =IFERROR(__xludf.DUMMYFUNCTION("""COMPUTED_VALUE"""),"Theodrek Heid") -> Theodrek Heid | O22: =IFERROR(__xludf.DUMMYFUNCTION("""COMPUTED_VALUE"""),"Jamais présent") -> Jamais présent
N23: =IFERROR(__xludf.DUMMYFUNCTION("""COMPUTED_VALUE"""),"Lucius Ravenshield") -> Lucius Ravenshield | O23: =IFERROR(__xludf.DUMMYFUNCTION("""COMPUTED_VALUE"""),"Jamais présent") -> Jamais présent
N24: =IFERROR(__xludf.DUMMYFUNCTION("""COMPUTED_VALUE"""),"Krakan Valyn") -> Krakan Valyn | O24: =IFERROR(__xludf.DUMMYFUNCTION("""COMPUTED_VALUE"""),"Jamais présent") -> Jamais présent
N25: =IFERROR(__xludf.DUMMYFUNCTION("""COMPUTED_VALUE"""),"Rusco") -> Rusco | O25: =IFERROR(__xludf.DUMMYFUNCTION("""COMPUTED_VALUE"""),"Jamais présent") -> Jamais présent
N26: =IFERROR(__xludf.DUMMYFUNCTION("""COMPUTED_VALUE"""),"Faynir") -> Faynir | O26: =IFERROR(__xludf.DUMMYFUNCTION("""COMPUTED_VALUE"""),"Jamais présent") -> Jamais présent
N27: =IFERROR(__xludf.DUMMYFUNCTION("""COMPUTED_VALUE"""),"Varaa Uzgar") -> Varaa Uzgar | O27: =IFERROR(__xludf.DUMMYFUNCTION("""COMPUTED_VALUE"""),"Jamais présent") -> Jamais présent
N28: =IFERROR(__xludf.DUMMYFUNCTION("""COMPUTED_VALUE"""),"Darius Blacktorn") -> Darius Blacktorn | O28: =IFERROR(__xludf.DUMMYFUNCTION("""COMPUTED_VALUE"""),"Jamais présent") -> Jamais présent
N47: Njalda

Sheet Effectifs
A1: Assermenté | B1: Grade | C1: Prénom | D1: Nom | E1: Corps | F1: Spécialité | G1: Status | H1: Métier | I1: Recrutement | J1: Jours travaillés | Z1: Grade Order
A2: TRUE | B2: Maréchal | C2: Lazabard | D2: Jemelred | E2: Etat-Major | F2: Garde, Collecteur de la garde | G2: En service actif | J2: =SUMIFS( 'Présences'!M:M, 'Présences'!D:D,C2, 'Présences'!E:E,D2 ) -> 4 | Z2: {=IF(B2:B988="",,MATCH(B2:B988,'Données'!A$2:A988,0))} -> 1
A3: TRUE | B3: Commander | C3: Filoki | E3: Etat-Major | F3: Garde, Collecteur de la garde | G3: En service actif | J3: =SUMIFS( 'Présences'!M:M, 'Présences'!D:D,C3, 'Présences'!E:E,D3 ) -> 0 | Z3: 2
A4: TRUE | B4: Major | C4: Dagbara | D4: Gronez | E4: Etat-Major | F4: Garde | G4: Mis en réserve | J4: =SUMIFS( 'Présences'!M:M, 'Présences'!D:D,C4, 'Présences'!E:E,D4 ) -> 0 | Z4: 3
A5: TRUE | B5: Capitaine | C5: Astrid | D5: Lame-Fine | E5: Cité de Blancherive | F5: Garde | G5: En service actif | H5: Chasseur | J5: =SUMIFS( 'Présences'!M:M, 'Présences'!D:D,C5, 'Présences'!E:E,D5 ) -> 10 | Z5: 4
A6: TRUE | B6: Capitaine | C6: Glaemorandir | D6: Oeil-Perçant | E6: Eclaireur | F6: Eclaireur, Garde | G6: En service actif | H6: Chasseur | I6: 46197 | J6: =SUMIFS( 'Présences'!M:M, 'Présences'!D:D,C6, 'Présences'!E:E,D6 ) -> 12 | Z6: 4
A7: TRUE | B7: Capitaine | C7: Edward | D7: Winters | E7: Cité de Blancherive | F7: Hird | G7: Mis en réserve | J7: =SUMIFS( 'Présences'!M:M, 'Présences'!D:D,C7, 'Présences'!E:E,D7 ) -> 0 | Z7: 4
A8: TRUE | B8: Capitaine | C8: Kah-Shir | D8: Sombre Griffe | E8: Faubourgs de Blancherive | F8: Garde, Collecteur de la garde | G8: En service actif | J8: =SUMIFS( 'Présences'!M:M, 'Présences'!D:D,C8, 'Présences'!E:E,D8 ) -> 4 | Z8: 4
A9: TRUE | B9: Capitaine | C9: Clemnir | D9: Arc-Vif | E9: Eclaireur | F9: Eclaireur | G9: Mort en service actif | H9: Chasseur | J9: =SUMIFS( 'Présences'!M:M, 'Présences'!D:D,C9, 'Présences'!E:E,D9 ) -> 0 | Z9: 4
A10: FALSE | B10: Capitaine | C10: Sigurd | D10: Grisetoison | E10: Rivebois | F10: Garde, Collecteur de la garde | G10: En service actif | J10: =SUMIFS( 'Présences'!M:M, 'Présences'!D:D,C10, 'Présences'!E:E,D10 ) -> 4 | Z10: 4
A11: FALSE | B11: Capitaine | C11: Hastelvin | E11: Cap Granite | F11: Garde, Collecteur de la garde | G11: En service actif | J11: =SUMIFS( 'Présences'!M:M, 'Présences'!D:D,C11, 'Présences'!E:E,D11 ) -> 0 | Z11: 4
A12: TRUE | B12: Lieutenant-Chef | C12: Ulfar | E12: Cité de Blancherive | F12: Garde, Instructeur | G12: En service actif | J12: =SUMIFS( 'Présences'!M:M, 'Présences'!D:D,C12, 'Présences'!E:E,D12 ) -> 0 | Z12: 5
A13: TRUE | B13: Lieutenant | C13: Ronin | E13: Cité de Blancherive | F13: Garde, Intendant de la garde, Collecteur de la garde | G13: En service actif | H13: Guerrier | I13: 46184 | J13: =SUMIFS( 'Présences'!M:M, 'Présences'!D:D,C13, 'Présences'!E:E,D13 ) -> 0 | Z13: 6
A14: TRUE | B14: Lieutenant | C14: Thorin | D14: Rivegel | E14: Cité de Blancherive | F14: Eclaireur, Garde | G14: En service actif | H14: Guerrier | J14: =SUMIFS( 'Présences'!M:M, 'Présences'!D:D,C14, 'Présences'!E:E,D14 ) -> 0 | Z14: 6
A15: TRUE | B15: Lieutenant-Chef | C15: Gisbern | D15: Isenbjorn | E15: Cité de Blancherive | F15: Garde | G15: En service actif | J15: =SUMIFS( 'Présences'!M:M, 'Présences'!D:D,C15, 'Présences'!E:E,D15 ) -> 5 | Z15: 5
A16: TRUE | B16: Sergent-Chef | C16: Rorik | D16: Marche-Hiver | E16: Cité de Blancherive | F16: Garde | G16: En service actif | J16: =SUMIFS( 'Présences'!M:M, 'Présences'!D:D,C16, 'Présences'!E:E,D16 ) -> 12 | Z16: 7
A17: TRUE | B17: Sergent-Chef | C17: Erwan | E17: Cité de Blancherive | F17: Garde | G17: En service actif | J17: =SUMIFS( 'Présences'!M:M, 'Présences'!D:D,C17, 'Présences'!E:E,D17 ) -> 0 | Z17: 7
A18: TRUE | B18: Lieutenant | C18: Daric | E18: Rivebois | F18: Garde | G18: En service actif | J18: =SUMIFS( 'Présences'!M:M, 'Présences'!D:D,C18, 'Présences'!E:E,D18 ) -> 0 | Z18: 6
A19: TRUE | B19: Caporal-Chef | C19: Ilflynn | E19: Cité de Blancherive | F19: Garde | G19: En service actif | J19: =SUMIFS( 'Présences'!M:M, 'Présences'!D:D,C19, 'Présences'!E:E,D19 ) -> 0 | Z19: 9
A20: TRUE | B20: Sergent-Chef | C20: Magnar | D20: Traquebrume | E20: Eclaireur | F20: Eclaireur, Garde | G20: En service actif | H20: Chasseur | I20: 46190 | J20: =SUMIFS( 'Présences'!M:M, 'Présences'!D:D,C20, 'Présences'!E:E,D20 ) -> 10 | Z20: 7
A21: TRUE | B21: Garde | C21: Pethiceor | D21: Le Borgne | E21: Eclaireur | F21: Eclaireur, Garde | G21: Mis en réserve | H21: Chasseur | I21: 46197 | J21: =SUMIFS( 'Présences'!M:M, 'Présences'!D:D,C21, 'Présences'!E:E,D21 ) -> 0 | Z21: 11
A22: TRUE | B22: Garde | C22: Laureen | D22: Toison-de-Sang | E22: Eclaireur | F22: Eclaireur, Garde | G22: En service actif | H22: Chasseur | I22: 46249 | J22: =SUMIFS( 'Présences'!M:M, 'Présences'!D:D,C22, 'Présences'!E:E,D22 ) -> 11 | Z22: 11
A23: FALSE | B23: Recrue | C23: Ma'arl | E23: Eclaireur | F23: Eclaireur, Garde | G23: En service actif | H23: Mineur | I23: 46259 | J23: =SUMIFS( 'Présences'!M:M, 'Présences'!D:D,C23, 'Présences'!E:E,D23 ) -> 0 | Z23: 13
A24: TRUE | B24: Garde | C24: Andor | D24: Viraes | E24: Cité de Blancherive | F24: Garde | G24: En service actif | J24: =SUMIFS( 'Présences'!M:M, 'Présences'!D:D,C24, 'Présences'!E:E,D24 ) -> 1 | Z24: 11
A25: FALSE | B25: Sergent-Chef | C25: Astrild | E25: Faubourgs de Blancherive | F25: Garde | G25: En service actif | J25: =SUMIFS( 'Présences'!M:M, 'Présences'!D:D,C25, 'Présences'!E:E,D25 ) -> 0 | Z25: 7
A26: TRUE | B26: Garde | C26: Athlan | E26: Cité de Blancherive | F26: Garde | G26: Démissionnaire | J26: =SUMIFS( 'Présences'!M:M, 'Présences'!D:D,C26, 'Présences'!E:E,D26 ) -> 0 | Z26: 11
A27: FALSE | B27: Lieutenant | C27: Encore-Un-Espoir | E27: Cité de Blancherive | F27: Garde, Tortionnaire, Instructeur | G27: En service actif | J27: =SUMIFS( 'Présences'!M:M, 'Présences'!D:D,C27, 'Présences'!E:E,D27 ) -> 0 | Z27: 6
A28: TRUE | B28: Garde | C28: Al'Dran | E28: Cité de Blancherive | F28: Garde | G28: En service actif | J28: =SUMIFS( 'Présences'!M:M, 'Présences'!D:D,C28, 'Présences'!E:E,D28 ) -> 0 | Z28: 11
A29: TRUE | B29: Garde | C29: Kendall | D29: Delamare | E29: Cité de Blancherive | F29: Garde | G29: En service actif | J29: =SUMIFS( 'Présences'!M:M, 'Présences'!D:D,C29, 'Présences'!E:E,D29 ) -> 7 | Z29: 11
A30: FALSE | B30: Garde | C30: Léonce | D30: Réve-épine | E30: Faubourgs de Blancherive | F30: Garde | G30: En service actif | J30: =SUMIFS( 'Présences'!M:M, 'Présences'!D:D,C30, 'Présences'!E:E,D30 ) -> 1 | Z30: 11
A31: FALSE | B31: Garde | C31: Kronk | D31: Grognon | E31: Hird du Jarl | F31: Hird | G31: En service actif | J31: =SUMIFS( 'Présences'!M:M, 'Présences'!D:D,C31, 'Présences'!E:E,D31 ) -> 0 | Z31: 11
A32: FALSE | B32: Garde | C32: Gronk | D32: Grognon | E32: Hird du Jarl | F32: Hird | G32: En service actif | J32: =SUMIFS( 'Présences'!M:M, 'Présences'!D:D,C32, 'Présences'!E:E,D32 ) -> 0 | Z32: 11
A33: FALSE | B33: Garde | C33: S'Khar | E33: Hird du Jarl | F33: Hird | G33: En service actif | J33: =SUMIFS( 'Présences'!M:M, 'Présences'!D:D,C33, 'Présences'!E:E,D33 ) -> 0 | Z33: 11
A34: FALSE | B34: Recrue | C34: Do'Rhazir | E34: Eclaireur | F34: Eclaireur, Garde | G34: En service actif | H34: Menuisier-Charbonnier | I34: 46261 | J34: =SUMIFS( 'Présences'!M:M, 'Présences'!D:D,C34, 'Présences'!E:E,D34 ) -> 0 | Z34: 13
A35: FALSE | B35: Cadet | C35: Eldrim | D35: Hache-Grise | E35: Cité de Blancherive | F35: Garde | G35: En service actif | J35: =SUMIFS( 'Présences'!M:M, 'Présences'!D:D,C35, 'Présences'!E:E,D35 ) -> 0 | Z35: 12
A36: FALSE | B36: Recrue | C36: Ro'minet | E36: Cité de Blancherive | F36: Garde | G36: Radié du service actif | J36: =SUMIFS( 'Présences'!M:M, 'Présences'!D:D,C36, 'Présences'!E:E,D36 ) -> 0 | Z36: 13
A37: FALSE | B37: Garde | C37: Bjorn | D37: Kornseen | E37: Cité de Blancherive | F37: Garde | G37: En service actif | J37: =SUMIFS( 'Présences'!M:M, 'Présences'!D:D,C37, 'Présences'!E:E,D37 ) -> 9 | Z37: 11
A38: FALSE | B38: Garde | C38: Wulfgar | D38: Durrock | E38: Cité de Blancherive | F38: Garde | G38: En service actif | J38: =SUMIFS( 'Présences'!M:M, 'Présences'!D:D,C38, 'Présences'!E:E,D38 ) -> 5 | Z38: 11
A39: FALSE | B39: Garde | C39: Lyosha | D39: Sullapierre | E39: Cité de Blancherive | F39: Garde | G39: Mis en réserve | J39: =SUMIFS( 'Présences'!M:M, 'Présences'!D:D,C39, 'Présences'!E:E,D39 ) -> 0 | Z39: 11
A40: FALSE | B40: Garde | C40: Brandon | D40: Alprazz | E40: Cité de Blancherive | F40: Garde | G40: Mis en réserve | J40: =SUMIFS( 'Présences'!M:M, 'Présences'!D:D,C40, 'Présences'!E:E,D40 ) -> 0 | Z40: 11
...

Sheet Présences
A1: Semaine | B1: Corps de garde | C1: Grade | D1: Prénom | E1: Nom | F1: Lun | G1: Mar | H1: Mer | I1: Jeu | J1: Ven | K1: Sam | L1: Dim | M1: Jours présents | N1: Solde | O1: Payé
A2: 35 | B2: Cap Granite | C2: Garde | D2: Bakhir | F2: FALSE | G2: FALSE | H2: FALSE | I2: FALSE | J2: FALSE | K2: FALSE | L2: FALSE | M2: =COUNTIF(F2:L2,TRUE) -> 0 | N2: =IF(OR(B2="Hird du Jarl",C2="Recrue"),0,IF(C2="Aspirant-Garde",M2*'Vue globale'!$L$2/2,M2*'Vue globale'!$L$2)) -> 0 | O2: FALSE
A3: 35 | B3: Cap Granite | C3: Garde | D3: Barnabas | E3: Tharmr | F3: FALSE | G3: FALSE | H3: FALSE | I3: FALSE | J3: FALSE | K3: FALSE | L3: FALSE | M3: =COUNTIF(F3:L3,TRUE) -> 0 | N3: =IF(OR(B3="Hird du Jarl",C3="Recrue"),0,IF(C3="Aspirant-Garde",M3*'Vue globale'!$L$2/2,M3*'Vue globale'!$L$2)) -> 0 | O3: FALSE
A4: 35 | B4: Cap Granite | C4: Garde | D4: Drakgor | E4: gro-Drakar | F4: FALSE | G4: FALSE | H4: FALSE | I4: FALSE | J4: FALSE | K4: FALSE | L4: FALSE | M4: =COUNTIF(F4:L4,TRUE) -> 0 | N4: =IF(OR(B4="Hird du Jarl",C4="Recrue"),0,IF(C4="Aspirant-Garde",M4*'Vue globale'!$L$2/2,M4*'Vue globale'!$L$2)) -> 0 | O4: FALSE | Q4: N'ajoutez jamais de ligne sur cette feuille. Si l'effectif a été modifié dans la page Effectifs, lancez le script "regenererSemaineCourante" pour ajouter les entrées manquantes ou changés tout en conservant les données précédentes.
A5: 35 | B5: Cap Granite | C5: Capitaine | D5: Hastelvin | F5: FALSE | G5: FALSE | H5: FALSE | I5: FALSE | J5: FALSE | K5: FALSE | L5: FALSE | M5: =COUNTIF(F5:L5,TRUE) -> 0 | N5: =IF(OR(B5="Hird du Jarl",C5="Recrue"),0,IF(C5="Aspirant-Garde",M5*'Vue globale'!$L$2/2,M5*'Vue globale'!$L$2)) -> 0 | O5: FALSE
A6: 35 | B6: Cap Granite | C6: Garde | D6: Malivor | E6: Xernes | F6: FALSE | G6: FALSE | H6: FALSE | I6: FALSE | J6: FALSE | K6: FALSE | L6: FALSE | M6: =COUNTIF(F6:L6,TRUE) -> 0 | N6: =IF(OR(B6="Hird du Jarl",C6="Recrue"),0,IF(C6="Aspirant-Garde",M6*'Vue globale'!$L$2/2,M6*'Vue globale'!$L$2)) -> 0 | O6: FALSE
A7: 35 | B7: Cap Granite | C7: Lieutenant-Chef | D7: Pavis | E7: Gurdalval | F7: FALSE | G7: FALSE | H7: FALSE | I7: FALSE | J7: FALSE | K7: FALSE | L7: FALSE | M7: =COUNTIF(F7:L7,TRUE) -> 0 | N7: =IF(OR(B7="Hird du Jarl",C7="Recrue"),0,IF(C7="Aspirant-Garde",M7*'Vue globale'!$L$2/2,M7*'Vue globale'!$L$2)) -> 0 | O7: FALSE
A8: 35 | B8: Cap Granite | C8: Garde | D8: Ragniir | E8: Coeurebene | F8: FALSE | G8: FALSE | H8: FALSE | I8: FALSE | J8: FALSE | K8: FALSE | L8: FALSE | M8: =COUNTIF(F8:L8,TRUE) -> 0 | N8: =IF(OR(B8="Hird du Jarl",C8="Recrue"),0,IF(C8="Aspirant-Garde",M8*'Vue globale'!$L$2/2,M8*'Vue globale'!$L$2)) -> 0 | O8: FALSE
A9: 35 | B9: Cap Granite | C9: Garde | D9: Starkos | E9: Coeurebene | F9: FALSE | G9: FALSE | H9: FALSE | I9: FALSE | J9: FALSE | K9: FALSE | L9: FALSE | M9: =COUNTIF(F9:L9,TRUE) -> 0 | N9: =IF(OR(B9="Hird du Jarl",C9="Recrue"),0,IF(C9="Aspirant-Garde",M9*'Vue globale'!$L$2/2,M9*'Vue globale'!$L$2)) -> 0 | O9: FALSE
A10: 35 | B10: Cité de Blancherive | C10: Garde | D10: Al'Dran | F10: TRUE | G10: TRUE | H10: TRUE | I10: TRUE | J10: TRUE | K10: TRUE | L10: TRUE | M10: =COUNTIF(F10:L10,TRUE) -> 7 | N10: =IF(OR(B10="Hird du Jarl",C10="Recrue"),0,IF(C10="Aspirant-Garde",M10*'Vue globale'!$L$2/2,M10*'Vue globale'!$L$2)) -> 350 | O10: FALSE
A11: 35 | B11: Cité de Blancherive | C11: Recrue | D11: Aldric | E11: Cendre-coeur | F11: FALSE | G11: FALSE | H11: FALSE | I11: FALSE | J11: FALSE | K11: TRUE | L11: FALSE | M11: =COUNTIF(F11:L11,TRUE) -> 1 | N11: =IF(OR(B11="Hird du Jarl",C11="Recrue"),0,IF(C11="Aspirant-Garde",M11*'Vue globale'!$L$2/2,M11*'Vue globale'!$L$2)) -> 0 | O11: FALSE
A12: 35 | B12: Cité de Blancherive | C12: Garde | D12: Andor | E12: Viraes | F12: FALSE | G12: TRUE | H12: FALSE | I12: FALSE | J12: FALSE | K12: FALSE | L12: FALSE | M12: =COUNTIF(F12:L12,TRUE) -> 1 | N12: =IF(OR(B12="Hird du Jarl",C12="Recrue"),0,IF(C12="Aspirant-Garde",M12*'Vue globale'!$L$2/2,M12*'Vue globale'!$L$2)) -> 50 | O12: FALSE
A13: 35 | B13: Cité de Blancherive | C13: Capitaine | D13: Astrid | E13: Lame-Fine | F13: TRUE | G13: TRUE | H13: TRUE | I13: FALSE | J13: TRUE | K13: TRUE | L13: TRUE | M13: =COUNTIF(F13:L13,TRUE) -> 6 | N13: =IF(OR(B13="Hird du Jarl",C13="Recrue"),0,IF(C13="Aspirant-Garde",M13*'Vue globale'!$L$2/2,M13*'Vue globale'!$L$2)) -> 300 | O13: TRUE
A14: 35 | B14: Cité de Blancherive | C14: Garde | D14: Athlan | F14: FALSE | G14: TRUE | H14: TRUE | I14: FALSE | J14: FALSE | K14: FALSE | L14: FALSE | M14: =COUNTIF(F14:L14,TRUE) -> 2 | N14: =IF(OR(B14="Hird du Jarl",C14="Recrue"),0,IF(C14="Aspirant-Garde",M14*'Vue globale'!$L$2/2,M14*'Vue globale'!$L$2)) -> 100 | O14: TRUE
A15: 35 | B15: Cité de Blancherive | C15: Garde | D15: Bjorn | E15: Kornseen | F15: TRUE | G15: TRUE | H15: FALSE | I15: TRUE | J15: FALSE | K15: TRUE | L15: TRUE | M15: =COUNTIF(F15:L15,TRUE) -> 5 | N15: =IF(OR(B15="Hird du Jarl",C15="Recrue"),0,IF(C15="Aspirant-Garde",M15*'Vue globale'!$L$2/2,M15*'Vue globale'!$L$2)) -> 250 | O15: TRUE
A16: 35 | B16: Cité de Blancherive | C16: Sergent | D16: Daric | F16: FALSE | G16: FALSE | H16: FALSE | I16: FALSE | J16: FALSE | K16: FALSE | L16: FALSE | M16: =COUNTIF(F16:L16,TRUE) -> 0 | N16: =IF(OR(B16="Hird du Jarl",C16="Recrue"),0,IF(C16="Aspirant-Garde",M16*'Vue globale'!$L$2/2,M16*'Vue globale'!$L$2)) -> 0 | O16: FALSE
A17: 35 | B17: Cité de Blancherive | C17: Aspirant-Garde | D17: Eldrim | E17: Hache-Grise | F17: FALSE | G17: FALSE | H17: FALSE | I17: FALSE | J17: FALSE | K17: FALSE | L17: FALSE | M17: =COUNTIF(F17:L17,TRUE) -> 0 | N17: =IF(OR(B17="Hird du Jarl",C17="Recrue"),0,IF(C17="Aspirant-Garde",M17*'Vue globale'!$L$2/2,M17*'Vue globale'!$L$2)) -> 0 | O17: FALSE
A18: 35 | B18: Cité de Blancherive | C18: Garde | D18: Encore-Un-Espoir | F18: FALSE | G18: FALSE | H18: FALSE | I18: FALSE | J18: FALSE | K18: FALSE | L18: FALSE | M18: =COUNTIF(F18:L18,TRUE) -> 0 | N18: =IF(OR(B18="Hird du Jarl",C18="Recrue"),0,IF(C18="Aspirant-Garde",M18*'Vue globale'!$L$2/2,M18*'Vue globale'!$L$2)) -> 0 | O18: FALSE
A19: 35 | B19: Cité de Blancherive | C19: Sergent | D19: Erwan | F19: TRUE | G19: TRUE | H19: FALSE | I19: TRUE | J19: FALSE | K19: TRUE | L19: TRUE | M19: =COUNTIF(F19:L19,TRUE) -> 5 | N19: =IF(OR(B19="Hird du Jarl",C19="Recrue"),0,IF(C19="Aspirant-Garde",M19*'Vue globale'!$L$2/2,M19*'Vue globale'!$L$2)) -> 250 | O19: TRUE
A20: 35 | B20: Cité de Blancherive | C20: Lieutenant | D20: Gisbern | E20: Isenbjorn | F20: TRUE | G20: TRUE | H20: FALSE | I20: FALSE | J20: TRUE | K20: FALSE | L20: FALSE | M20: =COUNTIF(F20:L20,TRUE) -> 3 | N20: =IF(OR(B20="Hird du Jarl",C20="Recrue"),0,IF(C20="Aspirant-Garde",M20*'Vue globale'!$L$2/2,M20*'Vue globale'!$L$2)) -> 150 | O20: FALSE
A21: 35 | B21: Cité de Blancherive | C21: Recrue | D21: Grub | F21: TRUE | G21: TRUE | H21: TRUE | I21: FALSE | J21: FALSE | K21: FALSE | L21: FALSE | M21: =COUNTIF(F21:L21,TRUE) -> 3 | N21: =IF(OR(B21="Hird du Jarl",C21="Recrue"),0,IF(C21="Aspirant-Garde",M21*'Vue globale'!$L$2/2,M21*'Vue globale'!$L$2)) -> 0 | O21: FALSE | Q21: Solde anticipée totale de la semaine courante | R21: =SUMIF('Présences'!A2:A702,ISOWEEKNUM(TODAY()),'Présences'!N2:N702) -> 5900
A22: 35 | B22: Cité de Blancherive | C22: Caporal-Chef | D22: Ilflynn | F22: TRUE | G22: TRUE | H22: TRUE | I22: TRUE | J22: TRUE | K22: TRUE | L22: TRUE | M22: =COUNTIF(F22:L22,TRUE) -> 7 | N22: =IF(OR(B22="Hird du Jarl",C22="Recrue"),0,IF(C22="Aspirant-Garde",M22*'Vue globale'!$L$2/2,M22*'Vue globale'!$L$2)) -> 350 | O22: TRUE | Q22: Solde totale à payer des semaines passés | R22: =SUMIFS( 'Présences'!N2:N702, 'Présences'!N2:N702,">0", 'Présences'!O2:O702,FALSE ) -> 6750
A23: 35 | B23: Cité de Blancherive | C23: Garde | D23: Kendall | E23: Delamare | F23: TRUE | G23: TRUE | H23: FALSE | I23: TRUE | J23: FALSE | K23: TRUE | L23: TRUE | M23: =COUNTIF(F23:L23,TRUE) -> 5 | N23: =IF(OR(B23="Hird du Jarl",C23="Recrue"),0,IF(C23="Aspirant-Garde",M23*'Vue globale'!$L$2/2,M23*'Vue globale'!$L$2)) -> 250 | O23: TRUE | Q23: Soldes impayés des semaines passés | R23: =COUNTIFS( 'Présences'!N2:N702,">0", 'Présences'!O2:O702,FALSE ) -> 40
A24: 35 | B24: Cité de Blancherive | C24: Recrue | D24: Léonce | E24: Réve-épine | F24: FALSE | G24: FALSE | H24: FALSE | I24: FALSE | J24: FALSE | K24: FALSE | L24: FALSE | M24: =COUNTIF(F24:L24,TRUE) -> 0 | N24: =IF(OR(B24="Hird du Jarl",C24="Recrue"),0,IF(C24="Aspirant-Garde",M24*'Vue globale'!$L$2/2,M24*'Vue globale'!$L$2)) -> 0 | O24: FALSE
A25: 35 | B25: Cité de Blancherive | C25: Recrue | D25: Ro'minet | F25: TRUE | G25: FALSE | H25: FALSE | I25: FALSE | J25: FALSE | K25: FALSE | L25: FALSE | M25: =COUNTIF(F25:L25,TRUE) -> 1 | N25: =IF(OR(B25="Hird du Jarl",C25="Recrue"),0,IF(C25="Aspirant-Garde",M25*'Vue globale'!$L$2/2,M25*'Vue globale'!$L$2)) -> 0 | O25: FALSE
A26: 35 | B26: Cité de Blancherive | C26: Lieutenant | D26: Ronin | F26: TRUE | G26: TRUE | H26: TRUE | I26: TRUE | J26: TRUE | K26: TRUE | L26: TRUE | M26: =COUNTIF(F26:L26,TRUE) -> 7 | N26: =IF(OR(B26="Hird du Jarl",C26="Recrue"),0,IF(C26="Aspirant-Garde",M26*'Vue globale'!$L$2/2,M26*'Vue globale'!$L$2)) -> 350 | O26: TRUE
A27: 35 | B27: Cité de Blancherive | C27: Sergent-Chef | D27: Rorik | E27: Marche-Hiver | F27: TRUE | G27: TRUE | H27: TRUE | I27: TRUE | J27: TRUE | K27: TRUE | L27: TRUE | M27: =COUNTIF(F27:L27,TRUE) -> 7 | N27: =IF(OR(B27="Hird du Jarl",C27="Recrue"),0,IF(C27="Aspirant-Garde",M27*'Vue globale'!$L$2/2,M27*'Vue globale'!$L$2)) -> 350 | O27: TRUE
A28: 35 | B28: Cité de Blancherive | C28: Lieutenant-Chef | D28: Ulfar | F28: TRUE | G28: FALSE | H28: TRUE | I28: FALSE | J28: TRUE | K28: FALSE | L28: TRUE | M28: =COUNTIF(F28:L28,TRUE) -> 4 | N28: =IF(OR(B28="Hird du Jarl",C28="Recrue"),0,IF(C28="Aspirant-Garde",M28*'Vue globale'!$L$2/2,M28*'Vue globale'!$L$2)) -> 200 | O28: FALSE
A29: 35 | B29: Cité de Blancherive | C29: Garde | D29: Wulfgar | E29: Durrock | F29: FALSE | G29: FALSE | H29: FALSE | I29: FALSE | J29: FALSE | K29: FALSE | L29: TRUE | M29: =COUNTIF(F29:L29,TRUE) -> 1 | N29: =IF(OR(B29="Hird du Jarl",C29="Recrue"),0,IF(C29="Aspirant-Garde",M29*'Vue globale'!$L$2/2,M29*'Vue globale'!$L$2)) -> 50 | O29: TRUE
A30: 35 | B30: Eclaireur | C30: Recrue | D30: Do'Rhazir | F30: FALSE | G30: FALSE | H30: FALSE | I30: FALSE | J30: TRUE | K30: TRUE | L30: TRUE | M30: =COUNTIF(F30:L30,TRUE) -> 3 | N30: =IF(OR(B30="Hird du Jarl",C30="Recrue"),0,IF(C30="Aspirant-Garde",M30*'Vue globale'!$L$2/2,M30*'Vue globale'!$L$2)) -> 0 | O30: TRUE
A31: 35 | B31: Eclaireur | C31: Capitaine | D31: Glaemorandir | E31: Oeil-Perçant | F31: TRUE | G31: TRUE | H31: TRUE | I31: TRUE | J31: TRUE | K31: TRUE | L31: TRUE | M31: =COUNTIF(F31:L31,TRUE) -> 7 | N31: =IF(OR(B31="Hird du Jarl",C31="Recrue"),0,IF(C31="Aspirant-Garde",M31*'Vue globale'!$L$2/2,M31*'Vue globale'!$L$2)) -> 350 | O31: TRUE
A32: 35 | B32: Eclaireur | C32: Garde | D32: Laureen | E32: Toison-de-Sang | F32: TRUE | G32: TRUE | H32: TRUE | I32: TRUE | J32: TRUE | K32: TRUE | L32: TRUE | M32: =COUNTIF(F32:L32,TRUE) -> 7 | N32: =IF(OR(B32="Hird du Jarl",C32="Recrue"),0,IF(C32="Aspirant-Garde",M32*'Vue globale'!$L$2/2,M32*'Vue globale'!$L$2)) -> 350 | O32: TRUE
A33: 35 | B33: Eclaireur | C33: Recrue | D33: Ma'arl | F33: FALSE | G33: TRUE | H33: TRUE | I33: FALSE | J33: TRUE | K33: TRUE | L33: TRUE | M33: =COUNTIF(F33:L33,TRUE) -> 5 | N33: =IF(OR(B33="Hird du Jarl",C33="Recrue"),0,IF(C33="Aspirant-Garde",M33*'Vue globale'!$L$2/2,M33*'Vue globale'!$L$2)) -> 0 | O33: TRUE
A34: 35 | B34: Eclaireur | C34: Garde | D34: Magnar | E34: Traquebrume | F34: TRUE | G34: TRUE | H34: TRUE | I34: TRUE | J34: TRUE | K34: FALSE | L34: TRUE | M34: =COUNTIF(F34:L34,TRUE) -> 6 | N34: =IF(OR(B34="Hird du Jarl",C34="Recrue"),0,IF(C34="Aspirant-Garde",M34*'Vue globale'!$L$2/2,M34*'Vue globale'!$L$2)) -> 300 | O34: TRUE
A35: 35 | B35: Eclaireur | C35: Lieutenant | D35: Thorin | E35: Rivegel | F35: FALSE | G35: FALSE | H35: FALSE | I35: FALSE | J35: FALSE | K35: FALSE | L35: FALSE | M35: =COUNTIF(F35:L35,TRUE) -> 0 | N35: =IF(OR(B35="Hird du Jarl",C35="Recrue"),0,IF(C35="Aspirant-Garde",M35*'Vue globale'!$L$2/2,M35*'Vue globale'!$L$2)) -> 0 | O35: FALSE
A36: 35 | B36: Etat-Major | C36: Commandant | D36: Filoki | F36: TRUE | G36: TRUE | H36: TRUE | I36: TRUE | J36: TRUE | K36: TRUE | L36: TRUE | M36: =COUNTIF(F36:L36,TRUE) -> 7 | N36: =IF(OR(B36="Hird du Jarl",C36="Recrue"),0,IF(C36="Aspirant-Garde",M36*'Vue globale'!$L$2/2,M36*'Vue globale'!$L$2)) -> 350 | O36: TRUE
A37: 35 | B37: Etat-Major | C37: Maréchal | D37: Lazabard | E37: Jemelred | F37: FALSE | G37: TRUE | H37: FALSE | I37: FALSE | J37: TRUE | K37: FALSE | L37: FALSE | M37: =COUNTIF(F37:L37,TRUE) -> 2 | N37: =IF(OR(B37="Hird du Jarl",C37="Recrue"),0,IF(C37="Aspirant-Garde",M37*'Vue globale'!$L$2/2,M37*'Vue globale'!$L$2)) -> 100 | O37: FALSE
A38: 35 | B38: Faubourgs de Blancherive | C38: Sergent-Chef | D38: Astrild | F38: FALSE | G38: FALSE | H38: FALSE | I38: FALSE | J38: FALSE | K38: FALSE | L38: FALSE | M38: =COUNTIF(F38:L38,TRUE) -> 0 | N38: =IF(OR(B38="Hird du Jarl",C38="Recrue"),0,IF(C38="Aspirant-Garde",M38*'Vue globale'!$L$2/2,M38*'Vue globale'!$L$2)) -> 0 | O38: FALSE
A39: 35 | B39: Faubourgs de Blancherive | C39: Garde | D39: Bernis | F39: FALSE | G39: FALSE | H39: FALSE | I39: FALSE | J39: FALSE | K39: FALSE | L39: FALSE | M39: =COUNTIF(F39:L39,TRUE) -> 0 | N39: =IF(OR(B39="Hird du Jarl",C39="Recrue"),0,IF(C39="Aspirant-Garde",M39*'Vue globale'!$L$2/2,M39*'Vue globale'!$L$2)) -> 0 | O39: FALSE
A40: 35 | B40: Faubourgs de Blancherive | C40: Garde | D40: Darina | F40: FALSE | G40: FALSE | H40: FALSE | I40: FALSE | J40: FALSE | K40: FALSE | L40: FALSE | M40: =COUNTIF(F40:L40,TRUE) -> 0 | N40: =IF(OR(B40="Hird du Jarl",C40="Recrue"),0,IF(C40="Aspirant-Garde",M40*'Vue globale'!$L$2/2,M40*'Vue globale'!$L$2)) -> 0 | O40: FALSE
...

Sheet Ravitaillement
A1: Element | B1: Quantité
A2: Vegetal Soup | B2: 161
A3: Beef Stew | B3: 81
A4: Venison Stew | B4: 137

Sheet Amendes
A1: Date | B1: Garde | C1: Contrevenant | D1: Infraction | E1: Montant | F1: Payé | G1: Reversé
A2: 46267.5 | B2: Sigurd Grisetoison | C2: Jean Eude | D2: Art. 117 — Du vol dans les fermes | E2: 40 | F2: TRUE | G2: TRUE
A3: 46267.5 | B3: Erwan | C3: 'Lechatblanc'' | D3: Art. 114 — De la marche obligatoire | E3: 15 | F3: TRUE | G3: FALSE
A4: 46268.5 | B4: Wulfgar Durrock | C4: Daran la collectionneur | D4: Art. 114 — De la marche obligatoire | E4: 15 | F4: TRUE | G4: TRUE
A5: 46268.5 | B5: Ulfar | C5: Emric de la tour | D5: Art. 115 — Du visage découvert | E5: 15 | F5: TRUE | G5: TRUE
A6: 46268.5 | B6: Ulfar | C6: Moren Mont Sombre | D6: Art. 115 — Du visage découvert | E6: 15 | F6: TRUE | G6: TRUE
A7: 46269.5 | B7: Glaemorandir Oeil-Perçant | C7: Lucor | D7: Art. 115 — Du visage découvert | E7: 15 | F7: TRUE | G7: FALSE
E12: {=IF(D12="","",IFERROR(_xlfn.XLOOKUP(D12,SyncCodex!L:L,SyncCodex!M:M),""))} | F12: FALSE | G12: FALSE
E13: {=IF(D13="","",IFERROR(_xlfn.XLOOKUP(D13,SyncCodex!L:L,SyncCodex!M:M),""))} | F13: FALSE | G13: FALSE
E14: {=IF(D14="","",IFERROR(_xlfn.XLOOKUP(D14,SyncCodex!L:L,SyncCodex!M:M),""))} | F14: FALSE | G14: FALSE
E15: {=IF(D15="","",IFERROR(_xlfn.XLOOKUP(D15,SyncCodex!L:L,SyncCodex!M:M),""))} | F15: FALSE | G15: FALSE
E16: {=IF(D16="","",IFERROR(_xlfn.XLOOKUP(D16,SyncCodex!L:L,SyncCodex!M:M),""))} | F16: FALSE | G16: FALSE
E17: {=IF(D17="","",IFERROR(_xlfn.XLOOKUP(D17,SyncCodex!L:L,SyncCodex!M:M),""))} | F17: FALSE | G17: FALSE
E18: {=IF(D18="","",IFERROR(_xlfn.XLOOKUP(D18,SyncCodex!L:L,SyncCodex!M:M),""))} | F18: FALSE | G18: FALSE
E19: {=IF(D19="","",IFERROR(_xlfn.XLOOKUP(D19,SyncCodex!L:L,SyncCodex!M:M),""))} | F19: FALSE | G19: FALSE
E20: {=IF(D20="","",IFERROR(_xlfn.XLOOKUP(D20,SyncCodex!L:L,SyncCodex!M:M),""))} | F20: FALSE | G20: FALSE
E21: {=IF(D21="","",IFERROR(_xlfn.XLOOKUP(D21,SyncCodex!L:L,SyncCodex!M:M),""))} | F21: FALSE | G21: FALSE
E22: {=IF(D22="","",IFERROR(_xlfn.XLOOKUP(D22,SyncCodex!L:L,SyncCodex!M:M),""))} | F22: FALSE | G22: FALSE
E23: {=IF(D23="","",IFERROR(_xlfn.XLOOKUP(D23,SyncCodex!L:L,SyncCodex!M:M),""))} | F23: FALSE | G23: FALSE
... E996: {=IF(D996="","",IFERROR(_xlfn.XLOOKUP(D996,SyncCodex!L:L,SyncCodex!M:M),""))} | F996: FALSE | G996: FALSE

Sheet Prison
A1: Date | B1: Garde | C1: Détenu | D1: Cellule | E1: Infraction | F1: Durée prévue | G1: Heure d'entrée | H1: Heure de sortie prévue | I1: Libéré | J1: Saisies sur la personne | K1: Motif / Notes
F3: {=IF(E3="","",IFERROR(_xlfn.XLOOKUP(E3,SyncCodex!N:N,SyncCodex!O:O),""))} | H3: =IF(OR(G3="",F3=""),"",G3+(F3/24)) | I3: FALSE
F4: {=IF(E4="","",IFERROR(_xlfn.XLOOKUP(E4,SyncCodex!N:N,SyncCodex!O:O),""))} | H4: =IF(OR(G4="",F4=""),"",G4+(F4/24)) | I4: FALSE
F5: {=IF(E5="","",IFERROR(_xlfn.XLOOKUP(E5,SyncCodex!N:N,SyncCodex!O:O),""))} | H5: =IF(OR(G5="",F5=""),"",G5+(F5/24)) | I5: FALSE
F6: {=IF(E6="","",IFERROR(_xlfn.XLOOKUP(E6,SyncCodex!N:N,SyncCodex!O:O),""))} | H6: =IF(OR(G6="",F6=""),"",G6+(F6/24)) | I6: FALSE
F7: {=IF(E7="","",IFERROR(_xlfn.XLOOKUP(E7,SyncCodex!N:N,SyncCodex!O:O),""))} | H7: =IF(OR(G7="",F7=""),"",G7+(F7/24)) | I7: FALSE
F8: {=IF(E8="","",IFERROR(_xlfn.XLOOKUP(E8,SyncCodex!N:N,SyncCodex!O:O),""))} | H8: =IF(OR(G8="",F8=""),"",G8+(F8/24)) | I8: FALSE
F9: {=IF(E9="","",IFERROR(_xlfn.XLOOKUP(E9,SyncCodex!N:N,SyncCodex!O:O),""))} | H9: =IF(OR(G9="",F9=""),"",G9+(F9/24)) | I9: FALSE
F10: {=IF(E10="","",IFERROR(_xlfn.XLOOKUP(E10,SyncCodex!N:N,SyncCodex!O:O),""))} | H10: =IF(OR(G10="",F10=""),"",G10+(F10/24)) | I10: FALSE
F11: {=IF(E11="","",IFERROR(_xlfn.XLOOKUP(E11,SyncCodex!N:N,SyncCodex!O:O),""))} | H11: =IF(OR(G11="",F11=""),"",G11+(F11/24)) | I11: FALSE
F12: {=IF(E12="","",IFERROR(_xlfn.XLOOKUP(E12,SyncCodex!N:N,SyncCodex!O:O),""))} | H12: =IF(OR(G12="",F12=""),"",G12+(F12/24)) | I12: FALSE
F13: {=IF(E13="","",IFERROR(_xlfn.XLOOKUP(E13,SyncCodex!N:N,SyncCodex!O:O),""))} | H13: =IF(OR(G13="",F13=""),"",G13+(F13/24)) | I13: FALSE
F14: {=IF(E14="","",IFERROR(_xlfn.XLOOKUP(E14,SyncCodex!N:N,SyncCodex!O:O),""))} | H14: =IF(OR(G14="",F14=""),"",G14+(F14/24)) | I14: FALSE
... F997: {=IF(E997="","",IFERROR(_xlfn.XLOOKUP(E997,SyncCodex!N:N,SyncCodex!O:O),""))} | H997: =IF(OR(G997="",F997=""),"",G997+(F997/24)) | I997: FALSE

Sheet Garde de Blancherive
A1: =IFERROR(__xludf.DUMMYFUNCTION("QUERY(Effectifs!A:Z, ""SELECT * WHERE E CONTAINS 'Cité' OR E CONTAINS 'Major' ORDER BY Z ASC"", 1)"),"Assermenté") -> Assermenté | B1: =IFERROR(__xludf.DUMMYFUNCTION("""COMPUTED_VALUE"""),"Grade") -> Grade | C1: =IFERROR(__xludf.DUMMYFUNCTION("""COMPUTED_VALUE"""),"Prénom") -> Prénom | D1: =IFERROR(__xludf.DUMMYFUNCTION("""COMPUTED_VALUE"""),"Nom") -> Nom | E1: =IFERROR(__xludf.DUMMYFUNCTION("""COMPUTED_VALUE"""),"Corps") -> Corps | F1: =IFERROR(__xludf.DUMMYFUNCTION("""COMPUTED_VALUE"""),"Spécialité") -> Spécialité | G1: =IFERROR(__xludf.DUMMYFUNCTION("""COMPUTED_VALUE"""),"Status") -> Status | H1: =IFERROR(__xludf.DUMMYFUNCTION("""COMPUTED_VALUE"""),"Métier") -> Métier | I1: =IFERROR(__xludf.DUMMYFUNCTION("""COMPUTED_VALUE"""),"Recrutement") -> Recrutement | J1: =IFERROR(__xludf.DUMMYFUNCTION("""COMPUTED_VALUE"""),"Jours travaillés") -> Jours travaillés | K1: =IFERROR(__xludf.DUMMYFUNCTION("""COMPUTED_VALUE"""),"") | L1: =IFERROR(__xludf.DUMMYFUNCTION("""COMPUTED_VALUE"""),"") | M1: =IFERROR(__xludf.DUMMYFUNCTION("""COMPUTED_VALUE"""),"") | N1: =IFERROR(__xludf.DUMMYFUNCTION("""COMPUTED_VALUE"""),"") | O1: =IFERROR(__xludf.DUMMYFUNCTION("""COMPUTED_VALUE"""),"") | P1: =IFERROR(__xludf.DUMMYFUNCTION("""COMPUTED_VALUE"""),"") | Q1: =IFERROR(__xludf.DUMMYFUNCTION("""COMPUTED_VALUE"""),"") | R1: =IFERROR(__xludf.DUMMYFUNCTION("""COMPUTED_VALUE"""),"") | ... Y1: =IFERROR(__xludf.DUMMYFUNCTION("""COMPUTED_VALUE"""),"") | Z1: =IFERROR(__xludf.DUMMYFUNCTION("""COMPUTED_VALUE"""),"Grade Order") -> Grade Order
A2: =IFERROR(__xludf.DUMMYFUNCTION("""COMPUTED_VALUE"""),TRUE) -> TRUE | B2: =IFERROR(__xludf.DUMMYFUNCTION("""COMPUTED_VALUE"""),"Maréchal") -> Maréchal | C2: =IFERROR(__xludf.DUMMYFUNCTION("""COMPUTED_VALUE"""),"Lazabard") -> Lazabard | D2: =IFERROR(__xludf.DUMMYFUNCTION("""COMPUTED_VALUE"""),"Jemelred") -> Jemelred | E2: =IFERROR(__xludf.DUMMYFUNCTION("""COMPUTED_VALUE"""),"Etat-Major") -> Etat-Major | F2: =IFERROR(__xludf.DUMMYFUNCTION("""COMPUTED_VALUE"""),"Garde, Collecteur de la garde") -> Garde, Collecteur de la garde | G2: =IFERROR(__xludf.DUMMYFUNCTION("""COMPUTED_VALUE"""),"En service actif") -> En service actif | J2: =IFERROR(__xludf.DUMMYFUNCTION("""COMPUTED_VALUE"""),4.0) -> 4 | Z2: =IFERROR(__xludf.DUMMYFUNCTION("""COMPUTED_VALUE"""),1.0) -> 1
A3: =IFERROR(__xludf.DUMMYFUNCTION("""COMPUTED_VALUE"""),TRUE) -> TRUE | B3: =IFERROR(__xludf.DUMMYFUNCTION("""COMPUTED_VALUE"""),"Commander") -> Commander | C3: =IFERROR(__xludf.DUMMYFUNCTION("""COMPUTED_VALUE"""),"Filoki") -> Filoki | E3: =IFERROR(__xludf.DUMMYFUNCTION("""COMPUTED_VALUE"""),"Etat-Major") -> Etat-Major | F3: =IFERROR(__xludf.DUMMYFUNCTION("""COMPUTED_VALUE"""),"Garde, Collecteur de la garde") -> Garde, Collecteur de la garde | G3: =IFERROR(__xludf.DUMMYFUNCTION("""COMPUTED_VALUE"""),"En service actif") -> En service actif | J3: =IFERROR(__xludf.DUMMYFUNCTION("""COMPUTED_VALUE"""),0.0) -> 0 | Z3: =IFERROR(__xludf.DUMMYFUNCTION("""COMPUTED_VALUE"""),2.0) -> 2
A4: =IFERROR(__xludf.DUMMYFUNCTION("""COMPUTED_VALUE"""),TRUE) -> TRUE | B4: =IFERROR(__xludf.DUMMYFUNCTION("""COMPUTED_VALUE"""),"Major") -> Major | C4: =IFERROR(__xludf.DUMMYFUNCTION("""COMPUTED_VALUE"""),"Dagbara") -> Dagbara | D4: =IFERROR(__xludf.DUMMYFUNCTION("""COMPUTED_VALUE"""),"Gronez") -> Gronez | E4: =IFERROR(__xludf.DUMMYFUNCTION("""COMPUTED_VALUE"""),"Etat-Major") -> Etat-Major | F4: =IFERROR(__xludf.DUMMYFUNCTION("""COMPUTED_VALUE"""),"Garde") -> Garde | G4: =IFERROR(__xludf.DUMMYFUNCTION("""COMPUTED_VALUE"""),"Mis en réserve") -> Mis en réserve | J4: =IFERROR(__xludf.DUMMYFUNCTION("""COMPUTED_VALUE"""),0.0) -> 0 | Z4: =IFERROR(__xludf.DUMMYFUNCTION("""COMPUTED_VALUE"""),3.0) -> 3
A5: =IFERROR(__xludf.DUMMYFUNCTION("""COMPUTED_VALUE"""),TRUE) -> TRUE | B5: =IFERROR(__xludf.DUMMYFUNCTION("""COMPUTED_VALUE"""),"Capitaine") -> Capitaine | C5: =IFERROR(__xludf.DUMMYFUNCTION("""COMPUTED_VALUE"""),"Astrid") -> Astrid | D5: =IFERROR(__xludf.DUMMYFUNCTION("""COMPUTED_VALUE"""),"Lame-Fine") -> Lame-Fine | E5: =IFERROR(__xludf.DUMMYFUNCTION("""COMPUTED_VALUE"""),"Cité de Blancherive") -> Cité de Blancherive | F5: =IFERROR(__xludf.DUMMYFUNCTION("""COMPUTED_VALUE"""),"Garde") -> Garde | G5: =IFERROR(__xludf.DUMMYFUNCTION("""COMPUTED_VALUE"""),"En service actif") -> En service actif | H5: =IFERROR(__xludf.DUMMYFUNCTION("""COMPUTED_VALUE"""),"Chasseur") -> Chasseur | J5: =IFERROR(__xludf.DUMMYFUNCTION("""COMPUTED_VALUE"""),10.0) -> 10 | Z5: =IFERROR(__xludf.DUMMYFUNCTION("""COMPUTED_VALUE"""),4.0) -> 4
A6: =IFERROR(__xludf.DUMMYFUNCTION("""COMPUTED_VALUE"""),TRUE) -> TRUE | B6: =IFERROR(__xludf.DUMMYFUNCTION("""COMPUTED_VALUE"""),"Capitaine") -> Capitaine | C6: =IFERROR(__xludf.DUMMYFUNCTION("""COMPUTED_VALUE"""),"Edward") -> Edward | D6: =IFERROR(__xludf.DUMMYFUNCTION("""COMPUTED_VALUE"""),"Winters") -> Winters | E6: =IFERROR(__xludf.DUMMYFUNCTION("""COMPUTED_VALUE"""),"Cité de Blancherive") -> Cité de Blancherive | F6: =IFERROR(__xludf.DUMMYFUNCTION("""COMPUTED_VALUE"""),"Hird") -> Hird | G6: =IFERROR(__xludf.DUMMYFUNCTION("""COMPUTED_VALUE"""),"Mis en réserve") -> Mis en réserve | J6: =IFERROR(__xludf.DUMMYFUNCTION("""COMPUTED_VALUE"""),0.0) -> 0 | Z6: =IFERROR(__xludf.DUMMYFUNCTION("""COMPUTED_VALUE"""),4.0) -> 4
A7: =IFERROR(__xludf.DUMMYFUNCTION("""COMPUTED_VALUE"""),TRUE) -> TRUE | B7: =IFERROR(__xludf.DUMMYFUNCTION("""COMPUTED_VALUE"""),"Lieutenant-Chef") -> Lieutenant-Chef | C7: =IFERROR(__xludf.DUMMYFUNCTION("""COMPUTED_VALUE"""),"Ulfar") -> Ulfar | E7: =IFERROR(__xludf.DUMMYFUNCTION("""COMPUTED_VALUE"""),"Cité de Blancherive") -> Cité de Blancherive | F7: =IFERROR(__xludf.DUMMYFUNCTION("""COMPUTED_VALUE"""),"Garde, Instructeur") -> Garde, Instructeur | G7: =IFERROR(__xludf.DUMMYFUNCTION("""COMPUTED_VALUE"""),"En service actif") -> En service actif | J7: =IFERROR(__xludf.DUMMYFUNCTION("""COMPUTED_VALUE"""),0.0) -> 0 | Z7: =IFERROR(__xludf.DUMMYFUNCTION("""COMPUTED_VALUE"""),5.0) -> 5
A8: =IFERROR(__xludf.DUMMYFUNCTION("""COMPUTED_VALUE"""),TRUE) -> TRUE | B8: =IFERROR(__xludf.DUMMYFUNCTION("""COMPUTED_VALUE"""),"Lieutenant-Chef") -> Lieutenant-Chef | C8: =IFERROR(__xludf.DUMMYFUNCTION("""COMPUTED_VALUE"""),"Gisbern") -> Gisbern | D8: =IFERROR(__xludf.DUMMYFUNCTION("""COMPUTED_VALUE"""),"Isenbjorn") -> Isenbjorn | E8: =IFERROR(__xludf.DUMMYFUNCTION("""COMPUTED_VALUE"""),"Cité de Blancherive") -> Cité de Blancherive | F8: =IFERROR(__xludf.DUMMYFUNCTION("""COMPUTED_VALUE"""),"Garde") -> Garde | G8: =IFERROR(__xludf.DUMMYFUNCTION("""COMPUTED_VALUE"""),"En service actif") -> En service actif | J8: =IFERROR(__xludf.DUMMYFUNCTION("""COMPUTED_VALUE"""),5.0) -> 5 | Z8: =IFERROR(__xludf.DUMMYFUNCTION("""COMPUTED_VALUE"""),5.0) -> 5
A9: =IFERROR(__xludf.DUMMYFUNCTION("""COMPUTED_VALUE"""),TRUE) -> TRUE | B9: =IFERROR(__xludf.DUMMYFUNCTION("""COMPUTED_VALUE"""),"Lieutenant") -> Lieutenant | C9: =IFERROR(__xludf.DUMMYFUNCTION("""COMPUTED_VALUE"""),"Ronin") -> Ronin | E9: =IFERROR(__xludf.DUMMYFUNCTION("""COMPUTED_VALUE"""),"Cité de Blancherive") -> Cité de Blancherive | F9: =IFERROR(__xludf.DUMMYFUNCTION("""COMPUTED_VALUE"""),"Garde, Intendant de la garde, Collecteur de la garde") -> Garde, Intendant de la garde, Collecteur de la garde | G9: =IFERROR(__xludf.DUMMYFUNCTION("""COMPUTED_VALUE"""),"En service actif") -> En service actif | H9: =IFERROR(__xludf.DUMMYFUNCTION("""COMPUTED_VALUE"""),"Guerrier") -> Guerrier | I9: =IFERROR(__xludf.DUMMYFUNCTION("""COMPUTED_VALUE"""),46184.0) -> 46184 | J9: =IFERROR(__xludf.DUMMYFUNCTION("""COMPUTED_VALUE"""),0.0) -> 0 | Z9: =IFERROR(__xludf.DUMMYFUNCTION("""COMPUTED_VALUE"""),6.0) -> 6
A10: =IFERROR(__xludf.DUMMYFUNCTION("""COMPUTED_VALUE"""),TRUE) -> TRUE | B10: =IFERROR(__xludf.DUMMYFUNCTION("""COMPUTED_VALUE"""),"Lieutenant") -> Lieutenant | C10: =IFERROR(__xludf.DUMMYFUNCTION("""COMPUTED_VALUE"""),"Thorin") -> Thorin | D10: =IFERROR(__xludf.DUMMYFUNCTION("""COMPUTED_VALUE"""),"Rivegel") -> Rivegel | E10: =IFERROR(__xludf.DUMMYFUNCTION("""COMPUTED_VALUE"""),"Cité de Blancherive") -> Cité de Blancherive | F10: =IFERROR(__xludf.DUMMYFUNCTION("""COMPUTED_VALUE"""),"Eclaireur, Garde") -> Eclaireur, Garde | G10: =IFERROR(__xludf.DUMMYFUNCTION("""COMPUTED_VALUE"""),"En service actif") -> En service actif | H10: =IFERROR(__xludf.DUMMYFUNCTION("""COMPUTED_VALUE"""),"Guerrier") -> Guerrier | J10: =IFERROR(__xludf.DUMMYFUNCTION("""COMPUTED_VALUE"""),0.0) -> 0 | Z10: =IFERROR(__xludf.DUMMYFUNCTION("""COMPUTED_VALUE"""),6.0) -> 6
A11: =IFERROR(__xludf.DUMMYFUNCTION("""COMPUTED_VALUE"""),FALSE) -> FALSE | B11: =IFERROR(__xludf.DUMMYFUNCTION("""COMPUTED_VALUE"""),"Lieutenant") -> Lieutenant | C11: =IFERROR(__xludf.DUMMYFUNCTION("""COMPUTED_VALUE"""),"Encore-Un-Espoir") -> Encore-Un-Espoir | E11: =IFERROR(__xludf.DUMMYFUNCTION("""COMPUTED_VALUE"""),"Cité de Blancherive") -> Cité de Blancherive | F11: =IFERROR(__xludf.DUMMYFUNCTION("""COMPUTED_VALUE"""),"Garde, Tortionnaire, Instructeur") -> Garde, Tortionnaire, Instructeur | G11: =IFERROR(__xludf.DUMMYFUNCTION("""COMPUTED_VALUE"""),"En service actif") -> En service actif | J11: =IFERROR(__xludf.DUMMYFUNCTION("""COMPUTED_VALUE"""),0.0) -> 0 | Z11: =IFERROR(__xludf.DUMMYFUNCTION("""COMPUTED_VALUE"""),6.0) -> 6
A12: =IFERROR(__xludf.DUMMYFUNCTION("""COMPUTED_VALUE"""),TRUE) -> TRUE | B12: =IFERROR(__xludf.DUMMYFUNCTION("""COMPUTED_VALUE"""),"Sergent-Chef") -> Sergent-Chef | C12: =IFERROR(__xludf.DUMMYFUNCTION("""COMPUTED_VALUE"""),"Rorik") -> Rorik | D12: =IFERROR(__xludf.DUMMYFUNCTION("""COMPUTED_VALUE"""),"Marche-Hiver") -> Marche-Hiver | E12: =IFERROR(__xludf.DUMMYFUNCTION("""COMPUTED_VALUE"""),"Cité de Blancherive") -> Cité de Blancherive | F12: =IFERROR(__xludf.DUMMYFUNCTION("""COMPUTED_VALUE"""),"Garde") -> Garde | G12: =IFERROR(__xludf.DUMMYFUNCTION("""COMPUTED_VALUE"""),"En service actif") -> En service actif | J12: =IFERROR(__xludf.DUMMYFUNCTION("""COMPUTED_VALUE"""),12.0) -> 12 | Z12: =IFERROR(__xludf.DUMMYFUNCTION("""COMPUTED_VALUE"""),7.0) -> 7
A13: =IFERROR(__xludf.DUMMYFUNCTION("""COMPUTED_VALUE"""),TRUE) -> TRUE | B13: =IFERROR(__xludf.DUMMYFUNCTION("""COMPUTED_VALUE"""),"Sergent-Chef") -> Sergent-Chef | C13: =IFERROR(__xludf.DUMMYFUNCTION("""COMPUTED_VALUE"""),"Erwan") -> Erwan | E13: =IFERROR(__xludf.DUMMYFUNCTION("""COMPUTED_VALUE"""),"Cité de Blancherive") -> Cité de Blancherive | F13: =IFERROR(__xludf.DUMMYFUNCTION("""COMPUTED_VALUE"""),"Garde") -> Garde | G13: =IFERROR(__xludf.DUMMYFUNCTION("""COMPUTED_VALUE"""),"En service actif") -> En service actif | J13: =IFERROR(__xludf.DUMMYFUNCTION("""COMPUTED_VALUE"""),0.0) -> 0 | Z13: =IFERROR(__xludf.DUMMYFUNCTION("""COMPUTED_VALUE"""),7.0) -> 7
A14: =IFERROR(__xludf.DUMMYFUNCTION("""COMPUTED_VALUE"""),TRUE) -> TRUE | B14: =IFERROR(__xludf.DUMMYFUNCTION("""COMPUTED_VALUE"""),"Caporal-Chef") -> Caporal-Chef | C14: =IFERROR(__xludf.DUMMYFUNCTION("""COMPUTED_VALUE"""),"Ilflynn") -> Ilflynn | E14: =IFERROR(__xludf.DUMMYFUNCTION("""COMPUTED_VALUE"""),"Cité de Blancherive") -> Cité de Blancherive | F14: =IFERROR(__xludf.DUMMYFUNCTION("""COMPUTED_VALUE"""),"Garde") -> Garde | G14: =IFERROR(__xludf.DUMMYFUNCTION("""COMPUTED_VALUE"""),"En service actif") -> En service actif | J14: =IFERROR(__xludf.DUMMYFUNCTION("""COMPUTED_VALUE"""),0.0) -> 0 | Z14: =IFERROR(__xludf.DUMMYFUNCTION("""COMPUTED_VALUE"""),9.0) -> 9
A15: =IFERROR(__xludf.DUMMYFUNCTION("""COMPUTED_VALUE"""),TRUE) -> TRUE | B15: =IFERROR(__xludf.DUMMYFUNCTION("""COMPUTED_VALUE"""),"Garde") -> Garde | C15: =IFERROR(__xludf.DUMMYFUNCTION("""COMPUTED_VALUE"""),"Andor") -> Andor | D15: =IFERROR(__xludf.DUMMYFUNCTION("""COMPUTED_VALUE"""),"Viraes") -> Viraes | E15: =IFERROR(__xludf.DUMMYFUNCTION("""COMPUTED_VALUE"""),"Cité de Blancherive") -> Cité de Blancherive | F15: =IFERROR(__xludf.DUMMYFUNCTION("""COMPUTED_VALUE"""),"Garde") -> Garde | G15: =IFERROR(__xludf.DUMMYFUNCTION("""COMPUTED_VALUE"""),"En service actif") -> En service actif | J15: =IFERROR(__xludf.DUMMYFUNCTION("""COMPUTED_VALUE"""),1.0) -> 1 | Z15: =IFERROR(__xludf.DUMMYFUNCTION("""COMPUTED_VALUE"""),11.0) -> 11
A16: =IFERROR(__xludf.DUMMYFUNCTION("""COMPUTED_VALUE"""),TRUE) -> TRUE | B16: =IFERROR(__xludf.DUMMYFUNCTION("""COMPUTED_VALUE"""),"Garde") -> Garde | C16: =IFERROR(__xludf.DUMMYFUNCTION("""COMPUTED_VALUE"""),"Athlan") -> Athlan | E16: =IFERROR(__xludf.DUMMYFUNCTION("""COMPUTED_VALUE"""),"Cité de Blancherive") -> Cité de Blancherive | F16: =IFERROR(__xludf.DUMMYFUNCTION("""COMPUTED_VALUE"""),"Garde") -> Garde | G16: =IFERROR(__xludf.DUMMYFUNCTION("""COMPUTED_VALUE"""),"Démissionnaire") -> Démissionnaire | J16: =IFERROR(__xludf.DUMMYFUNCTION("""COMPUTED_VALUE"""),0.0) -> 0 | Z16: =IFERROR(__xludf.DUMMYFUNCTION("""COMPUTED_VALUE"""),11.0) -> 11
A17: =IFERROR(__xludf.DUMMYFUNCTION("""COMPUTED_VALUE"""),TRUE) -> TRUE | B17: =IFERROR(__xludf.DUMMYFUNCTION("""COMPUTED_VALUE"""),"Garde") -> Garde | C17: =IFERROR(__xludf.DUMMYFUNCTION("""COMPUTED_VALUE"""),"Al'Dran") -> Al'Dran | E17: =IFERROR(__xludf.DUMMYFUNCTION("""COMPUTED_VALUE"""),"Cité de Blancherive") -> Cité de Blancherive | F17: =IFERROR(__xludf.DUMMYFUNCTION("""COMPUTED_VALUE"""),"Garde") -> Garde | G17: =IFERROR(__xludf.DUMMYFUNCTION("""COMPUTED_VALUE"""),"En service actif") -> En service actif | J17: =IFERROR(__xludf.DUMMYFUNCTION("""COMPUTED_VALUE"""),0.0) -> 0 | Z17: =IFERROR(__xludf.DUMMYFUNCTION("""COMPUTED_VALUE"""),11.0) -> 11
A18: =IFERROR(__xludf.DUMMYFUNCTION("""COMPUTED_VALUE"""),TRUE) -> TRUE | B18: =IFERROR(__xludf.DUMMYFUNCTION("""COMPUTED_VALUE"""),"Garde") -> Garde | C18: =IFERROR(__xludf.DUMMYFUNCTION("""COMPUTED_VALUE"""),"Kendall") -> Kendall | D18: =IFERROR(__xludf.DUMMYFUNCTION("""COMPUTED_VALUE"""),"Delamare") -> Delamare | E18: =IFERROR(__xludf.DUMMYFUNCTION("""COMPUTED_VALUE"""),"Cité de Blancherive") -> Cité de Blancherive | F18: =IFERROR(__xludf.DUMMYFUNCTION("""COMPUTED_VALUE"""),"Garde") -> Garde | G18: =IFERROR(__xludf.DUMMYFUNCTION("""COMPUTED_VALUE"""),"En service actif") -> En service actif | J18: =IFERROR(__xludf.DUMMYFUNCTION("""COMPUTED_VALUE"""),7.0) -> 7 | Z18: =IFERROR(__xludf.DUMMYFUNCTION("""COMPUTED_VALUE"""),11.0) -> 11
A19: =IFERROR(__xludf.DUMMYFUNCTION("""COMPUTED_VALUE"""),FALSE) -> FALSE | B19: =IFERROR(__xludf.DUMMYFUNCTION("""COMPUTED_VALUE"""),"Garde") -> Garde | C19: =IFERROR(__xludf.DUMMYFUNCTION("""COMPUTED_VALUE"""),"Bjorn") -> Bjorn | D19: =IFERROR(__xludf.DUMMYFUNCTION("""COMPUTED_VALUE"""),"Kornseen") -> Kornseen | E19: =IFERROR(__xludf.DUMMYFUNCTION("""COMPUTED_VALUE"""),"Cité de Blancherive") -> Cité de Blancherive | F19: =IFERROR(__xludf.DUMMYFUNCTION("""COMPUTED_VALUE"""),"Garde") -> Garde | G19: =IFERROR(__xludf.DUMMYFUNCTION("""COMPUTED_VALUE"""),"En service actif") -> En service actif | J19: =IFERROR(__xludf.DUMMYFUNCTION("""COMPUTED_VALUE"""),9.0) -> 9 | Z19: =IFERROR(__xludf.DUMMYFUNCTION("""COMPUTED_VALUE"""),11.0) -> 11
A20: =IFERROR(__xludf.DUMMYFUNCTION("""COMPUTED_VALUE"""),FALSE) -> FALSE | B20: =IFERROR(__xludf.DUMMYFUNCTION("""COMPUTED_VALUE"""),"Garde") -> Garde | C20: =IFERROR(__xludf.DUMMYFUNCTION("""COMPUTED_VALUE"""),"Wulfgar") -> Wulfgar | D20: =IFERROR(__xludf.DUMMYFUNCTION("""COMPUTED_VALUE"""),"Durrock") -> Durrock | E20: =IFERROR(__xludf.DUMMYFUNCTION("""COMPUTED_VALUE"""),"Cité de Blancherive") -> Cité de Blancherive | F20: =IFERROR(__xludf.DUMMYFUNCTION("""COMPUTED_VALUE"""),"Garde") -> Garde | G20: =IFERROR(__xludf.DUMMYFUNCTION("""COMPUTED_VALUE"""),"En service actif") -> En service actif | J20: =IFERROR(__xludf.DUMMYFUNCTION("""COMPUTED_VALUE"""),5.0) -> 5 | Z20: =IFERROR(__xludf.DUMMYFUNCTION("""COMPUTED_VALUE"""),11.0) -> 11
A21: =IFERROR(__xludf.DUMMYFUNCTION("""COMPUTED_VALUE"""),FALSE) -> FALSE | B21: =IFERROR(__xludf.DUMMYFUNCTION("""COMPUTED_VALUE"""),"Garde") -> Garde | C21: =IFERROR(__xludf.DUMMYFUNCTION("""COMPUTED_VALUE"""),"Lyosha ") -> Lyosha | D21: =IFERROR(__xludf.DUMMYFUNCTION("""COMPUTED_VALUE"""),"Sullapierre") -> Sullapierre | E21: =IFERROR(__xludf.DUMMYFUNCTION("""COMPUTED_VALUE"""),"Cité de Blancherive") -> Cité de Blancherive | F21: =IFERROR(__xludf.DUMMYFUNCTION("""COMPUTED_VALUE"""),"Garde") -> Garde | G21: =IFERROR(__xludf.DUMMYFUNCTION("""COMPUTED_VALUE"""),"Mis en réserve") -> Mis en réserve | J21: =IFERROR(__xludf.DUMMYFUNCTION("""COMPUTED_VALUE"""),0.0) -> 0 | Z21: =IFERROR(__xludf.DUMMYFUNCTION("""COMPUTED_VALUE"""),11.0) -> 11
A22: =IFERROR(__xludf.DUMMYFUNCTION("""COMPUTED_VALUE"""),FALSE) -> FALSE | B22: =IFERROR(__xludf.DUMMYFUNCTION("""COMPUTED_VALUE"""),"Garde") -> Garde | C22: =IFERROR(__xludf.DUMMYFUNCTION("""COMPUTED_VALUE"""),"Brandon ") -> Brandon | D22: =IFERROR(__xludf.DUMMYFUNCTION("""COMPUTED_VALUE"""),"Alprazz") -> Alprazz | E22: =IFERROR(__xludf.DUMMYFUNCTION("""COMPUTED_VALUE"""),"Cité de Blancherive") -> Cité de Blancherive | F22: =IFERROR(__xludf.DUMMYFUNCTION("""COMPUTED_VALUE"""),"Garde") -> Garde | G22: =IFERROR(__xludf.DUMMYFUNCTION("""COMPUTED_VALUE"""),"Mis en réserve") -> Mis en réserve | J22: =IFERROR(__xludf.DUMMYFUNCTION("""COMPUTED_VALUE"""),0.0) -> 0 | Z22: =IFERROR(__xludf.DUMMYFUNCTION("""COMPUTED_VALUE"""),11.0) -> 11
A23: =IFERROR(__xludf.DUMMYFUNCTION("""COMPUTED_VALUE"""),FALSE) -> FALSE | B23: =IFERROR(__xludf.DUMMYFUNCTION("""COMPUTED_VALUE"""),"Garde") -> Garde | C23: =IFERROR(__xludf.DUMMYFUNCTION("""COMPUTED_VALUE"""),"Selene") -> Selene | E23: =IFERROR(__xludf.DUMMYFUNCTION("""COMPUTED_VALUE"""),"Cité de Blancherive") -> Cité de Blancherive | F23: =IFERROR(__xludf.DUMMYFUNCTION("""COMPUTED_VALUE"""),"Garde") -> Garde | G23: =IFERROR(__xludf.DUMMYFUNCTION("""COMPUTED_VALUE"""),"Mis en réserve") -> Mis en réserve | J23: =IFERROR(__xludf.DUMMYFUNCTION("""COMPUTED_VALUE"""),0.0) -> 0 | Z23: =IFERROR(__xludf.DUMMYFUNCTION("""COMPUTED_VALUE"""),11.0) -> 11
A24: =IFERROR(__xludf.DUMMYFUNCTION("""COMPUTED_VALUE"""),FALSE) -> FALSE | B24: =IFERROR(__xludf.DUMMYFUNCTION("""COMPUTED_VALUE"""),"Cadet") -> Cadet | C24: =IFERROR(__xludf.DUMMYFUNCTION("""COMPUTED_VALUE"""),"Eldrim") -> Eldrim | D24: =IFERROR(__xludf.DUMMYFUNCTION("""COMPUTED_VALUE"""),"Hache-Grise") -> Hache-Grise | E24: =IFERROR(__xludf.DUMMYFUNCTION("""COMPUTED_VALUE"""),"Cité de Blancherive") -> Cité de Blancherive | F24: =IFERROR(__xludf.DUMMYFUNCTION("""COMPUTED_VALUE"""),"Garde") -> Garde | G24: =IFERROR(__xludf.DUMMYFUNCTION("""COMPUTED_VALUE"""),"En service actif") -> En service actif | J24: =IFERROR(__xludf.DUMMYFUNCTION("""COMPUTED_VALUE"""),0.0) -> 0 | Z24: =IFERROR(__xludf.DUMMYFUNCTION("""COMPUTED_VALUE"""),12.0) -> 12
A25: =IFERROR(__xludf.DUMMYFUNCTION("""COMPUTED_VALUE"""),FALSE) -> FALSE | B25: =IFERROR(__xludf.DUMMYFUNCTION("""COMPUTED_VALUE"""),"Recrue") -> Recrue | C25: =IFERROR(__xludf.DUMMYFUNCTION("""COMPUTED_VALUE"""),"Ro'minet") -> Ro'minet | E25: =IFERROR(__xludf.DUMMYFUNCTION("""COMPUTED_VALUE"""),"Cité de Blancherive") -> Cité de Blancherive | F25: =IFERROR(__xludf.DUMMYFUNCTION("""COMPUTED_VALUE"""),"Garde") -> Garde | G25: =IFERROR(__xludf.DUMMYFUNCTION("""COMPUTED_VALUE"""),"Radié du service actif") -> Radié du service actif | J25: =IFERROR(__xludf.DUMMYFUNCTION("""COMPUTED_VALUE"""),0.0) -> 0 | Z25: =IFERROR(__xludf.DUMMYFUNCTION("""COMPUTED_VALUE"""),13.0) -> 13
A26: =IFERROR(__xludf.DUMMYFUNCTION("""COMPUTED_VALUE"""),FALSE) -> FALSE | B26: =IFERROR(__xludf.DUMMYFUNCTION("""COMPUTED_VALUE"""),"Recrue") -> Recrue | C26: =IFERROR(__xludf.DUMMYFUNCTION("""COMPUTED_VALUE"""),"Aldric") -> Aldric | D26: =IFERROR(__xludf.DUMMYFUNCTION("""COMPUTED_VALUE"""),"Cendre-coeur") -> Cendre-coeur | E26: =IFERROR(__xludf.DUMMYFUNCTION("""COMPUTED_VALUE"""),"Cité de Blancherive") -> Cité de Blancherive | F26: =IFERROR(__xludf.DUMMYFUNCTION("""COMPUTED_VALUE"""),"Garde") -> Garde | G26: =IFERROR(__xludf.DUMMYFUNCTION("""COMPUTED_VALUE"""),"En service actif") -> En service actif | J26: =IFERROR(__xludf.DUMMYFUNCTION("""COMPUTED_VALUE"""),2.0) -> 2 | Z26: =IFERROR(__xludf.DUMMYFUNCTION("""COMPUTED_VALUE"""),13.0) -> 13
A27: =IFERROR(__xludf.DUMMYFUNCTION("""COMPUTED_VALUE"""),FALSE) -> FALSE | B27: =IFERROR(__xludf.DUMMYFUNCTION("""COMPUTED_VALUE"""),"Recrue") -> Recrue | C27: =IFERROR(__xludf.DUMMYFUNCTION("""COMPUTED_VALUE"""),"Aldrok") -> Aldrok | E27: =IFERROR(__xludf.DUMMYFUNCTION("""COMPUTED_VALUE"""),"Cité de Blancherive") -> Cité de Blancherive | F27: =IFERROR(__xludf.DUMMYFUNCTION("""COMPUTED_VALUE"""),"Garde") -> Garde | G27: =IFERROR(__xludf.DUMMYFUNCTION("""COMPUTED_VALUE"""),"Radié du service actif") -> Radié du service actif | I27: =IFERROR(__xludf.DUMMYFUNCTION("""COMPUTED_VALUE"""),46265.0) -> 46265 | J27: =IFERROR(__xludf.DUMMYFUNCTION("""COMPUTED_VALUE"""),0.0) -> 0 | Z27: =IFERROR(__xludf.DUMMYFUNCTION("""COMPUTED_VALUE"""),13.0) -> 13
A28: =IFERROR(__xludf.DUMMYFUNCTION("""COMPUTED_VALUE"""),FALSE) -> FALSE | B28: =IFERROR(__xludf.DUMMYFUNCTION("""COMPUTED_VALUE"""),"Recrue") -> Recrue | C28: =IFERROR(__xludf.DUMMYFUNCTION("""COMPUTED_VALUE"""),"Zeid") -> Zeid | D28: =IFERROR(__xludf.DUMMYFUNCTION("""COMPUTED_VALUE"""),"Le Brise-Lames") -> Le Brise-Lames | E28: =IFERROR(__xludf.DUMMYFUNCTION("""COMPUTED_VALUE"""),"Cité de Blancherive") -> Cité de Blancherive | F28: =IFERROR(__xludf.DUMMYFUNCTION("""COMPUTED_VALUE"""),"Garde") -> Garde | G28: =IFERROR(__xludf.DUMMYFUNCTION("""COMPUTED_VALUE"""),"En service actif") -> En service actif | I28: =IFERROR(__xludf.DUMMYFUNCTION("""COMPUTED_VALUE"""),46266.0) -> 46266 | J28: =IFERROR(__xludf.DUMMYFUNCTION("""COMPUTED_VALUE"""),2.0) -> 2 | Z28: =IFERROR(__xludf.DUMMYFUNCTION("""COMPUTED_VALUE"""),13.0) -> 13
A29: =IFERROR(__xludf.DUMMYFUNCTION("""COMPUTED_VALUE"""),FALSE) -> FALSE | B29: =IFERROR(__xludf.DUMMYFUNCTION("""COMPUTED_VALUE"""),"Recrue") -> Recrue | C29: =IFERROR(__xludf.DUMMYFUNCTION("""COMPUTED_VALUE"""),"Gruseldorf") -> Gruseldorf | D29: =IFERROR(__xludf.DUMMYFUNCTION("""COMPUTED_VALUE"""),"E. Jackeet") -> E. Jackeet | E29: =IFERROR(__xludf.DUMMYFUNCTION("""COMPUTED_VALUE"""),"Cité de Blancherive") -> Cité de Blancherive | F29: =IFERROR(__xludf.DUMMYFUNCTION("""COMPUTED_VALUE"""),"Garde") -> Garde | G29: =IFERROR(__xludf.DUMMYFUNCTION("""COMPUTED_VALUE"""),"Radié du service actif") -> Radié du service actif | I29: =IFERROR(__xludf.DUMMYFUNCTION("""COMPUTED_VALUE"""),46264.0) -> 46264 | J29: =IFERROR(__xludf.DUMMYFUNCTION("""COMPUTED_VALUE"""),0.0) -> 0 | Z29: =IFERROR(__xludf.DUMMYFUNCTION("""COMPUTED_VALUE"""),13.0) -> 13
A30: =IFERROR(__xludf.DUMMYFUNCTION("""COMPUTED_VALUE"""),FALSE) -> FALSE | B30: =IFERROR(__xludf.DUMMYFUNCTION("""COMPUTED_VALUE"""),"Recrue") -> Recrue | C30: =IFERROR(__xludf.DUMMYFUNCTION("""COMPUTED_VALUE"""),"Mordecai") -> Mordecai | D30: =IFERROR(__xludf.DUMMYFUNCTION("""COMPUTED_VALUE"""),"E. Jackeet") -> E. Jackeet | E30: =IFERROR(__xludf.DUMMYFUNCTION("""COMPUTED_VALUE"""),"Cité de Blancherive") -> Cité de Blancherive | F30: =IFERROR(__xludf.DUMMYFUNCTION("""COMPUTED_VALUE"""),"Garde") -> Garde | G30: =IFERROR(__xludf.DUMMYFUNCTION("""COMPUTED_VALUE"""),"Radié du service actif") -> Radié du service actif | I30: =IFERROR(__xludf.DUMMYFUNCTION("""COMPUTED_VALUE"""),46264.0) -> 46264 | J30: =IFERROR(__xludf.DUMMYFUNCTION("""COMPUTED_VALUE"""),0.0) -> 0 | Z30: =IFERROR(__xludf.DUMMYFUNCTION("""COMPUTED_VALUE"""),13.0) -> 13

Sheet Garde des Faubourgs
